Workbook

Sheet Выходные
A1: 45658
A2: 45659
A3: 45660
A4: 45661
A5: 45662
A6: 45663
A7: 45664
A8: 45665
A9: 45668
A10: 45669
A11: 45675
A12: 45676
... A236: 46387

Sheet history_import_log
A1: ts | B1: level | C1: message
A2: 46117.754 | B2: START | C2: Историческая загрузка. Период: 2026-01-01 - 2026-01-31
A3: 46117.754 | B3: RESULT | C3: Файл 01010404.xls: импортировано строк 572
A4: 46117.754 | B4: SUMMARY | C4: Исторический импорт отчётов: файлов просмотрено 1, файлов с данными 1, строк импортировано 572
A5: 46117.754 | B5: WARN | C5: Не найден лист точки для QR: 0
A6: 46117.757 | B6: SUMMARY | C6: Исторический QR пересчёт завершён. Период: 2026-01-01 - 2026-01-31, режим отметки E: без изменений
A7: 46117.758 | B7: DONE | C7: Финализация листов точек и дашборда завершена
A8: 46117.758 | B8: DONE | C8: Историческая загрузка завершена. Период: 2026-01-01 - 2026-01-31
A9: 46117.76 | B9: START | C9: Историческая загрузка. Период: 2026-01-01 - 2026-04-04
A10: 46117.76 | B10: WARN | C10: Не найден лист точки: 201
A11: 46117.76 | B11: RESULT | C11: Файл 01010404.xls: импортировано строк 1952
A12: 46117.76 | B12: SUMMARY | C12: Исторический импорт отчётов: файлов просмотрено 1, файлов с данными 1, строк импортировано 1952
A13: 46117.76 | B13: WARN | C13: Не найден лист точки для QR: 0
... A44: 46117.786 | B44: DONE | C44: Историческая загрузка завершена. Период: 2026-03-16 - 2026-04-04

Sheet import_log
A1: ts | B1: level | C1: fileName | D1: message | E1: extra
A2: 46112.382 | B2: ERROR | C2: 3424336.xls | D2: Drive.Files.insert is not a function
A3: 46112.382 | B3: SUMMARY | D3: Итог запуска. Всего файлов: 1, успешно: 0, с ошибками: 1, пропущено: 0
A4: 46112.383 | B4: ERROR | C4: 3424336.xls | D4: Drive.Files.insert is not a function
A5: 46112.383 | B5: SUMMARY | D5: Итог запуска. Всего файлов: 1, успешно: 0, с ошибками: 1, пропущено: 0
A6: 46112.383 | B6: ERROR | C6: 3424336.xls | D6: Drive.Files.insert is not a function
A7: 46112.383 | B7: SUMMARY | D7: Итог запуска. Всего файлов: 1, успешно: 0, с ошибками: 1, пропущено: 0
A8: 46112.386 | B8: RESULT | C8: 3424336.xls | D8: Успешно импортировано строк: 21
A9: 46112.386 | B9: WARN | C9: 3424336.xls | D9: Нет прав на удаление файла из папки: Access denied: DriveApp.
A10: 46112.386 | B10: SUMMARY | D10: Итог запуска. Всего файлов: 1, успешно: 1, с ошибками: 0, пропущено: 0
A11: 46112.391 | B11: SUMMARY | D11: Итог запуска. Всего файлов: 1, успешно: 0, с ошибками: 0, пропущено: 1
A12: 46113.266 | B12: SUMMARY | D12: Итог запуска. Всего файлов: 0, успешно: 0, с ошибками: 0, пропущено: 0
A13: 46114.266 | B13: RESULT | C13: 6578358.xls | D13: Успешно импортировано строк: 19
A14: 46114.267 | B14: WARN | C14: 6578358.xls | D14: Нет прав на удаление файла из папки: Access denied: DriveApp.
A15: 46114.267 | B15: RESULT | C15: 4881807.xls | D15: Успешно импортировано строк: 21
A16: 46114.267 | B16: WARN | C16: 4881807.xls | D16: Нет прав на удаление файла из папки: Access denied: DriveApp.
A17: 46114.267 | B17: RESULT | C17: 5770234.xls | D17: Успешно импортировано строк: 21
A18: 46114.267 | B18: WARN | C18: 5770234.xls | D18: Нет прав на удаление файла из папки: Access denied: DriveApp.
A19: 46114.267 | B19: SUMMARY | D19: Итог запуска. Всего файлов: 3, успешно: 3, с ошибками: 0, пропущено: 0
A20: 46114.595 | B20: SUMMARY | D20: Итог запуска. Всего файлов: 3, успешно: 0, с ошибками: 0, пропущено: 3
A21: 46114.596 | B21: SUMMARY | D21: Итог запуска. Всего файлов: 3, успешно: 0, с ошибками: 0, пропущено: 3
A22: 46114.596 | B22: SUMMARY | D22: Итог запуска. Всего файлов: 3, успешно: 0, с ошибками: 0, пропущено: 3
A23: 46114.627 | B23: SUMMARY | D23: Итог запуска. Всего файлов: 0, успешно: 0, с ошибками: 0, пропущено: 0
A24: 46115.355 | B24: RESULT | C24: 6580532.xlsx | D24: Успешно импортировано строк: 21
A25: 46115.355 | B25: WARN | C25: 6580532.xlsx | D25: Нет прав на удаление файла из папки: Доступ запрещен: DriveApp.
A26: 46115.355 | B26: SUMMARY | D26: Итог запуска. Всего файлов: 1, успешно: 1, с ошибками: 0, пропущено: 0
A27: 46115.445 | B27: SUMMARY | D27: Итог запуска. Всего файлов: 1, успешно: 0, с ошибками: 0, пропущено: 1
A28: 46116.266 | B28: SUMMARY | D28: Итог запуска. Всего файлов: 0, успешно: 0, с ошибками: 0, пропущено: 0
A29: 46117.266 | B29: SUMMARY | D29: Итог запуска. Всего файлов: 0, успешно: 0, с ошибками: 0, пропущено: 0
A30: 46118.267 | B30: RESULT | C30: 9683379.xls | D30: Успешно импортировано строк: 20
A31: 46118.267 | B31: WARN | C31: 9683379.xls | D31: Нет прав на удаление файла из папки: Access denied: DriveApp.
A32: 46118.267 | B32: SUMMARY | D32: Итог запуска. Всего файлов: 1, успешно: 1, с ошибками: 0, пропущено: 0
A33: 46118.679 | B33: SUMMARY | D33: Итог запуска. Всего файлов: 1, успешно: 0, с ошибками: 0, пропущено: 1
A34: 46118.693 | B34: RESULT | C34: 03040504.xls | D34: Успешно импортировано строк: 65
A35: 46118.693 | B35: WARN | C35: 03040504.xls | D35: Нет прав на удаление файла из папки: Доступ запрещен: DriveApp.
A36: 46118.693 | B36: SUMMARY | D36: Итог запуска. Всего файлов: 1, успешно: 1, с ошибками: 0, пропущено: 0
A37: 46118.706 | B37: RESULT | C37: 01040504.xlsx | D37: Успешно импортировано строк: 3
A38: 46118.706 | B38: WARN | C38: 01040504.xlsx | D38: Нет прав на удаление файла из папки: Доступ запрещен: DriveApp.
A39: 46118.706 | B39: SUMMARY | D39: Итог запуска. Всего файлов: 1, успешно: 1, с ошибками: 0, пропущено: 0
A40: 46119.27 | B40: RESULT | C40: 1656302.xls | D40: Успешно импортировано строк: 25
...

Sheet Скидки
A1: Точка | B1: Тип периода | C1: Время начала | D1: Время окончания | E1: Механика | F1: Суть акции | G1: Скидка | H1: Цель | I1: Комментарий
A2: 1 | B2: Пик | C2: 0.5 | D2: 0.66666667 | E2: Бандл | F2: Кухня + Напиток | G2: -15% на напиток | H2: Рост среднего чека | I2: Скидка только на доп.позицию
A3: 1 | B3: Пик | C3: 0.75 | D3: 0.79166667 | E3: Бандл | F3: Кухня + Десерт | G3: -15% на десерт | H3: Рост среднего чека | I3: Апселл сладкого
A4: 1 | B4: Просадка | C4: 0.83333333 | D4: 0.91666667 | E4: Скидка категории | F4: Десерты | G4: -0.2 | H4: Стимул покупки | I4: Короткое окно
A7: 2 | B7: Пик | C7: 0.33333333 | D7: 0.41666667 | E7: Бандл | F7: Кухня (завтрак) + Напиток | G7: -15% на напиток | H7: Рост среднего чека | I7: Утренний поток
A8: 2 | B8: Пик | C8: 0.45833333 | D8: 0.54166667 | E8: Бандл | F8: Кухня + Десерт | G8: -10% на десерт | H8: Рост среднего чека | I8: Не резать ядро
A9: 2 | B9: Просадка | C9: 0.58333333 | D9: 0.66666667 | E9: Скидка категории | F9: Десерты | G9: -0.2 | H9: Стимул покупки | I9: Послеобеденный спад
A12: 3 | B12: Пик | C12: 0.33333333 | D12: 0.41666667 | E12: Бандл | F12: Кухня (завтрак) + Напиток | G12: -15% на напиток | H12: Рост среднего чека | I12: Классический апселл
A13: 3 | B13: Пик | C13: 0.5 | D13: 0.58333333 | E13: Бандл | F13: Кухня + Снеки | G13: -15% на снеки | H13: Рост среднего чека | I13: Допродажа к обеду
A14: 3 | B14: Просадка | C14: 0.70833333 | D14: 0.79166667 | E14: Скидка категории | F14: Десерты | G14: -0.2 | H14: Стимул покупки | I14: После работы
A16: 4 | B16: Пик | C16: 0.33333333 | D16: 0.375 | E16: Бандл | F16: Кухня (завтрак) + Напиток | G16: -10% на напиток | H16: Рост среднего чека | I16: Небольшая скидка
A17: 4 | B17: Пик | C17: 0.45833333 | D17: 0.54166667 | E17: Бандл | F17: Япония + Напиток | G17: -10% на напиток | H17: Рост среднего чека | I17: Конкуренция со столовой
A18: 4 | B18: Просадка | C18: 0.58333333 | D18: 0.66666667 | E18: Скидка категории | F18: Десерты | G18: -0.2 | H18: Стимул покупки | I18: Послеобеденный спад
A21: 5 | B21: Пик | C21: 0.375 | D21: 0.41666667 | E21: Бандл | F21: Кухня (завтрак) + Напиток | G21: -15% на напиток | H21: Рост среднего чека | I21: Утренний поток
A22: 5 | B22: Пик | C22: 0.5 | D22: 0.58333333 | E22: Бандл | F22: Кухня + Десерт | G22: -15% на десерт | H22: Рост среднего чека | I22: Обеденный поток
A23: 5 | B23: Просадка | C23: 0.625 | D23: 0.66666667 | E23: Скидка категории | F23: Десерты | G23: -0.2 | H23: Стимул покупки | I23: Перекус
A25: 6 | B25: Пик | C25: 0.33333333 | D25: 0.41666667 | E25: Бандл | F25: Кухня (завтрак) + Напиток | G25: -15% на напиток | H25: Рост среднего чека | I25: Утро
A26: 6 | B26: Пик | C26: 0.45833333 | D26: 0.54166667 | E26: Бандл | F26: Кухня + Снеки | G26: -15% на снеки | H26: Рост среднего чека | I26: Обед
A27: 6 | B27: Просадка | C27: 0.58333333 | D27: 0.66666667 | E27: Скидка категории | F27: Десерты | G27: -0.2 | H27: Стимул покупки | I27: Послеобеденный спад
A30: 7
A31: 7
A32: 7
A34: 8 | B34: Пик | C34: 0.33333333 | D34: 0.375 | E34: Бандл | F34: Кухня (завтрак) + Напиток | G34: -10% на напиток | H34: Рост среднего чека | I34: Сотрудники, утро
A35: 8 | B35: Пик | C35: 0.45833333 | D35: 0.54166667 | E35: Бандл | F35: Кухня + Десерт | G35: -10% на десерт | H35: Рост среднего чека | I35: Обед
A36: 8 | B36: Просадка | C36: 0.58333333 | D36: 0.66666667 | E36: Скидка категории | F36: Десерты | G36: -0.2 | H36: Стимул покупки | I36: Послеобеденный спад
A39: 9 | B39: Пик | C39: 0.33333333 | D39: 0.45833333 | E39: Бандл | F39: Кухня + Напиток | G39: -15% на напиток | H39: Рост среднего чека | I39: Утро
A40: 9 | B40: Пик | C40: 0.5 | D40: 0.58333333 | E40: Бандл | F40: Япония + Напиток | G40: -15% на напиток | H40: Рост среднего чека | I40: Обед
A41: 9 | B41: Просадка | C41: 0.625 | D41: 0.70833333 | E41: Скидка категории | F41: Снеки | G41: -0.2 | H41: Стимул покупки | I41: Перекус
A44: 10 | B44: Пик | C44: 0.29166667 | D44: 0.41666667 | E44: Бандл | F44: Кухня (завтрак) + Напиток | G44: -15% на напиток | H44: Рост среднего чека | I44: Смена/утро
A45: 10 | B45: Пик | C45: 0.45833333 | D45: 0.54166667 | E45: Бандл | F45: Кухня + Десерт | G45: -15% на десерт | H45: Рост среднего чека | I45: Обед
A46: 10 | B46: Просадка | C46: 0 | D46: 0.25 | E46: Скидка категории | F46: Напитки | G46: -0.2 | H46: Стимул покупки | I46: Ночь: дешевле по марже
A47: 10 | B47: Просадка | C47: 0.70833333 | D47: 0.75 | E47: Скидка категории | F47: Десерты или Снеки | G47: -0.2 | H47: Стимул покупки | I47: Перекус
A49: 11
A50: 11
A51: 11
A53: 12 | B53: Пик | C53: 0.33333333 | D53: 0.41666667 | E53: Бандл | F53: Кухня (завтрак) + Напиток | G53: -10% на напиток | H53: Рост среднего чека | I53: Не конфликтовать с комплексами
A54: 12 | B54: Пик | C54: 0.45833333 | D54: 0.54166667 | E54: Бандл | F54: Кухня + Десерт | G54: -10% на десерт | H54: Рост среднего чека | I54: Скидка на доп.позицию
A55: 12 | B55: Просадка | C55: 0.58333333 | D55: 0.66666667 | E55: Скидка категории | F55: Десерты | G55: -0.2 | H55: Стимул покупки | I55: Послеобеденный спад
A58: 13 | B58: Пик | C58: 0.33333333 | D58: 0.41666667 | E58: Бандл | F58: Кухня (завтрак) + Напиток | G58: -10% на напиток | H58: Рост среднего чека | I58: Утро
A59: 13 | B59: Пик | C59: 0.45833333 | D59: 0.54166667 | E59: Бандл | F59: Кухня + Десерт | G59: -10% на десерт | H59: Рост среднего чека | I59: Обед
...

Sheet шаблон
A1: Точка | C1: Дата запуска | E1: Тип точки | G1: Активна | K1: Стоимость обслуживания | L1: Аренда | M1: Коммуналка | N1: Клининг
A2: Среднее | K2: =SUM(L2:Q2) -> 0
A3: Дата | B3: $ QR-код | C3: $ Касса | D3: $ Итог | E3: Чеки QR | F3: Чеки Касса | G3: Чеки Итог | H3: Ср.-й чек | I3: Списания | J3: д/н

Sheet Рентабельность точек
A1: Для расчёта приняты средние данные из листа Дашборд
B2: рент.50% | C2: 9500 | F2: 30 | G2: 30 | J2: 24
A3: Точка № | B3: Min выручка для рент 50% | C3: Ср.-я выручка | D3: Логистика | E3: Списания | F3: Аренда в день | G3: Связь в день | H3: Рентабельность | I3: Фин-рез день | J3: Фин-рез мес | L3: Рентабельность точек %
A4: ='Дашборд'!A5 -> 1 | B4: =(D4+E4+F4+G4)/(1-(1/2.8)-0.5) -> 9285.8836 | C4: ='Дашборд'!B5 -> 17400.554 | D4: 550 | E4: ='Дашборд'!E5 -> 699.88813 | F4: ='Дашборд'!AH3/$F$2 -> 76.666667 | H4: =(I4/C4)*100% -> 0.56662079 | I4: =C4-(C4/2.8)-D4-E4-F4-G4 -> 9859.5156 | J4: =I4*$J$2 -> 236628.37
A5: ='Дашборд'!A6 -> 2 | B5: =(D5+E5+F5+G5)/(1-(1/2.8)-0.5) -> 5219.8451 | C5: ='Дашборд'!B6 -> 5056.7733 | D5: 550 | E5: ='Дашборд'!E6 -> 185.69216 | F5: ='Дашборд'!AH4/$F$2 -> 10 | H5: =(I5/C5)*100% -> 0.49539312 | I5: =C5-(C5/2.8)-D5-E5-F5-G5 -> 2505.0907 | J5: =I5*$J$2 -> 60122.176
A6: ='Дашборд'!A7 -> 3 | B6: =(D6+E6+F6+G6)/(1-(1/2.8)-0.5) -> 17523.551 | C6: ='Дашборд'!B7 -> 7694.3712 | D6: 1700 | E6: ='Дашборд'!E7 -> 673.63115 | F6: ='Дашборд'!AH5/$F$2 -> 129.73333 | H6: =(I6/C6)*100% -> 0.31750703 | I6: =C6-(C6/2.8)-D6-E6-F6-G6 -> 2443.017 | J6: =I6*$J$2 -> 58632.407
A7: ='Дашборд'!A8 -> 4 | B7: =(D7+E7+F7+G7)/(1-(1/2.8)-0.5) -> 12589.022 | C7: ='Дашборд'!B8 -> 2941.4374 | D7: 550 | E7: ='Дашборд'!E8 -> 1248.4317 | F7: ='Дашборд'!AH6/$F$2 -> 0 | H7: =(I7/C7)*100% -> 0.031444607 | I7: =C7-(C7/2.8)-D7-E7-F7-G7 -> 92.492343 | J7: =I7*$J$2 -> 2219.8162
A8: ='Дашборд'!A9 -> 5 | B8: =(D8+E8+F8+G8)/(1-(1/2.8)-0.5) -> 7069.0723 | C8: ='Дашборд'!B9 -> 14822.316 | D8: 550 | E8: ='Дашборд'!E9 -> 449.86747 | F8: ='Дашборд'!AH7/$F$2 -> 10 | H8: =(I8/C8)*100% -> 0.57472559 | I8: =C8-(C8/2.8)-D8-E8-F8-G8 -> 8518.7642 | J8: =I8*$J$2 -> 204450.34
A9: ='Дашборд'!A10 -> 6 | B9: =(D9+E9+F9+G9)/(1-(1/2.8)-0.5) -> 8344.8024 | C9: ='Дашборд'!B10 -> 9760.7927 | D9: 550 | E9: ='Дашборд'!E10 -> 520.84796 | F9: ='Дашборд'!AH8/$F$2 -> 121.26667 | H9: =(I9/C9)*100% -> 0.52072417 | I9: =C9-(C9/2.8)-D9-E9-F9-G9 -> 5082.6807 | J9: =I9*$J$2 -> 121984.34
A10: ='Дашборд'!A11 -> 7 | B10: =(D10+E10+F10+G10)/(1-(1/2.8)-0.5) -> 5594.7014 | C10: ='Дашборд'!B11 -> 5577.0686 | D10: 550 | E10: ='Дашборд'!E11 -> 239.24305 | F10: ='Дашборд'!AH9/$F$2 -> 10 | H10: =(I10/C10)*100% -> 0.49954834 | I10: =C10-(C10/2.8)-D10-E10-F10-G10 -> 2786.0153 | J10: =I10*$J$2 -> 66864.368
A11: ='Дашборд'!A12 -> 8 | B11: =(D11+E11+F11+G11)/(1-(1/2.8)-0.5) -> 7007.7844 | C11: ='Дашборд'!B12 -> 7437.8164 | D11: 550 | E11: ='Дашборд'!E12 -> 257.44539 | F11: ='Дашборд'!AH10/$F$2 -> 193.66667 | H11: =(I11/C11)*100% -> 0.50825957 | I11: =C11-(C11/2.8)-D11-E11-F11-G11 -> 3780.3414 | J11: =I11*$J$2 -> 90728.193
A12: ='Дашборд'!A13 -> 9 | B12: =(D12+E12+F12+G12)/(1-(1/2.8)-0.5) -> 7612.9472 | C12: ='Дашборд'!B13 -> 10341.419 | D12: 550 | E12: ='Дашборд'!E13 -> 207.56388 | F12: ='Дашборд'!AH11/$F$2 -> 330 | H12: =(I12/C12)*100% -> 0.53769132 | I12: =C12-(C12/2.8)-D12-E12-F12-G12 -> 5560.4915 | J12: =I12*$J$2 -> 133451.8
A13: ='Дашборд'!A14 -> 10 | B13: =(D13+E13+F13+G13)/(1-(1/2.8)-0.5) -> 8680.3951 | C13: ='Дашборд'!B14 -> 9886.613 | D13: 550 | E13: ='Дашборд'!E14 -> 563.05645 | F13: ='Дашборд'!AH12/$F$2 -> 127 | H13: =(I13/C13)*100% -> 0.51742931 | I13: =C13-(C13/2.8)-D13-E13-F13-G13 -> 5115.6234 | J13: =I13*$J$2 -> 122774.96
A14: ='Дашборд'!A15 -> 11 | B14: =(D14+E14+F14+G14)/(1-(1/2.8)-0.5) -> 0 | C14: ='Дашборд'!B15 | E14: ='Дашборд'!E15 | F14: ='Дашборд'!AH13/$F$2 -> 0 | H14: =(I14/C14)*100% -> #DIV/0! | I14: =C14-(C14/2.8)-D14-E14-F14-G14 -> 0 | J14: =I14*$J$2 -> 0
A15: ='Дашборд'!A16 -> 12 | B15: =(D15+E15+F15+G15)/(1-(1/2.8)-0.5) -> 6527.6113 | C15: ='Дашборд'!B16 -> 6144.2566 | D15: 550 | E15: ='Дашборд'!E16 -> 222.51589 | F15: ='Дашборд'!AH14/$F$2 -> 160 | H15: =(I15/C15)*100% -> 0.49108681 | I15: =C15-(C15/2.8)-D15-E15-F15-G15 -> 3017.3634 | J15: =I15*$J$2 -> 72416.721
A16: ='Дашборд'!A17 -> 13 | B16: =(D16+E16+F16+G16)/(1-(1/2.8)-0.5) -> 6826.9549 | C16: ='Дашборд'!B17 -> 6274.8255 | D16: 550 | E16: ='Дашборд'!E17 -> 265.27927 | F16: ='Дашборд'!AH15/$F$2 -> 160 | H16: =(I16/C16)*100% -> 0.48742983 | I16: =C16-(C16/2.8)-D16-E16-F16-G16 -> 3058.5371 | J16: =I16*$J$2 -> 73404.891
A17: ='Дашборд'!A18 -> 14 | B17: =(D17+E17+F17+G17)/(1-(1/2.8)-0.5) -> 7847.0915 | C17: ='Дашборд'!B18 -> 11786.44 | D17: 550 | E17: ='Дашборд'!E18 -> 345.51307 | F17: ='Дашборд'!AH16/$F$2 -> 225.5 | H17: =(I17/C17)*100% -> 0.54774674 | I17: =C17-(C17/2.8)-D17-E17-F17-G17 -> 6455.984 | J17: =I17*$J$2 -> 154943.62
A18: ='Дашборд'!A19 -> 15 | B18: =(D18+E18+F18+G18)/(1-(1/2.8)-0.5) -> 6663.0202 | C18: ='Дашборд'!B19 -> 8637.9245 | D18: 550 | E18: ='Дашборд'!E19 -> 308.52669 | F18: ='Дашборд'!AH17/$F$2 -> 93.333333 | H18: =(I18/C18)*100% -> 0.53266169 | I18: =C18-(C18/2.8)-D18-E18-F18-G18 -> 4601.0914 | J18: =I18*$J$2 -> 110426.19
A19: ='Дашборд'!A20 -> 16 | B19: =(D19+E19+F19+G19)/(1-(1/2.8)-0.5) -> 5591.8195 | C19: ='Дашборд'!B20 -> 7918.1447 | D19: 550 | E19: ='Дашборд'!E20 -> 238.83135 | F19: ='Дашборд'!AH18/$F$2 -> 10 | H19: =(I19/C19)*100% -> 0.54197097 | I19: =C19-(C19/2.8)-D19-E19-F19-G19 -> 4291.4045 | J19: =I19*$J$2 -> 102993.71
A20: ='Дашборд'!A21 -> 17 | B20: =(D20+E20+F20+G20)/(1-(1/2.8)-0.5) -> 8556.2839 | C20: ='Дашборд'!B21 -> 6951.1225 | D20: 550 | E20: ='Дашборд'!E21 -> 437.35961 | F20: ='Дашборд'!AH19/$F$2 -> 234.96667 | H20: =(I20/C20)*100% -> 0.46701126 | I20: =C20-(C20/2.8)-D20-E20-F20-G20 -> 3246.2525 | J20: =I20*$J$2 -> 77910.06
A21: ='Дашборд'!A22 -> 18 | B21: =(D21+E21+F21+G21)/(1-(1/2.8)-0.5) -> 9795.54 | C21: ='Дашборд'!B22 -> 6322.1 | D21: 550 | E21: ='Дашборд'!E22 -> 839.36286 | F21: ='Дашборд'!AH20/$F$2 -> 10 | H21: =(I21/C21)*100% -> 0.42151252 | I21: =C21-(C21/2.8)-D21-E21-F21-G21 -> 2664.8443 | J21: =I21*$J$2 -> 63956.263
A22: ='Дашборд'!A23 -> 19 | B22: =(D22+E22+F22+G22)/(1-(1/2.8)-0.5) -> 6466.4096 | C22: ='Дашборд'!B23 -> 6887.1429 | D22: 550 | E22: ='Дашборд'!E23 -> 299.13946 | F22: ='Дашборд'!AH21/$F$2 -> 74.633333 | H22: =(I22/C22)*100% -> 0.5087271 | I22: =C22-(C22/2.8)-D22-E22-F22-G22 -> 3503.6762 | J22: =I22*$J$2 -> 84088.228
A23: ='Дашборд'!A24 -> 20 | B23: =(D23+E23+F23+G23)/(1-(1/2.8)-0.5) -> 8965.7968 | C23: ='Дашборд'!B24 -> 15616.147 | D23: 550 | E23: ='Дашборд'!E24 -> 610.62811 | F23: ='Дашборд'!AH22/$F$2 -> 120.2 | H23: =(I23/C23)*100% -> 0.56083767 | I23: =C23-(C23/2.8)-D23-E23-F23-G23 -> 8758.1238 | J23: =I23*$J$2 -> 210194.97 | L23: Рентабельность точек по месяцу в рублях
A24: ='Дашборд'!A25 -> 21 | B24: =(D24+E24+F24+G24)/(1-(1/2.8)-0.5) -> 6209.0328 | C24: ='Дашборд'!B25 -> 7178.7581 | D24: 550 | E24: ='Дашборд'!E25 -> 264.33801 | F24: ='Дашборд'!AH23/$F$2 -> 72.666667 | H24: =(I24/C24)*100% -> 0.51929751 | I24: =C24-(C24/2.8)-D24-E24-F24-G24 -> 3727.9112 | J24: =I24*$J$2 -> 89469.87
A25: ='Дашборд'!A26 -> 22 | B25: =(D25+E25+F25+G25)/(1-(1/2.8)-0.5) -> 7357.6028 | C25: ='Дашборд'!B26 -> 6456.0993 | D25: 550 | E25: ='Дашборд'!E26 -> 424.41945 | F25: ='Дашборд'!AH24/$F$2 -> 76.666667 | H25: =(I25/C25)*100% -> 0.48005201 | I25: =C25-(C25/2.8)-D25-E25-F25-G25 -> 3099.2634 | J25: =I25*$J$2 -> 74382.323
A26: ='Дашборд'!A27 -> 23 | B26: =(D26+E26+F26+G26)/(1-(1/2.8)-0.5) -> 6566.5197 | C26: ='Дашборд'!B27 -> 9432.3562 | D26: 550 | E26: ='Дашборд'!E27 -> 311.40757 | F26: ='Дашборд'!AH25/$F$2 -> 76.666667 | H26: =(I26/C26)*100% -> 0.54340434 | I26: =C26-(C26/2.8)-D26-E26-F26-G26 -> 5125.5833 | J26: =I26*$J$2 -> 123014
A27: ='Дашборд'!A28 -> 24 | B27: =(D27+E27+F27+G27)/(1-(1/2.8)-0.5) -> 7796.5183 | C27: ='Дашборд'!B28 -> 7901.369 | D27: 550 | E27: ='Дашборд'!E28 -> 553.78833 | F27: ='Дашборд'!AH26/$F$2 -> 10 | H27: =(I27/C27)*100% -> 0.50189571 | I27: =C27-(C27/2.8)-D27-E27-F27-G27 -> 3965.6632 | J27: =I27*$J$2 -> 95175.916
A28: ='Дашборд'!A29 -> 25 | B28: =(D28+E28+F28+G28)/(1-(1/2.8)-0.5) -> 6512.5954 | C28: ='Дашборд'!B29 -> 5921.2846 | D28: 550 | E28: ='Дашборд'!E29 -> 370.37077 | F28: ='Дашборд'!AH27/$F$2 -> 10 | H28: =(I28/C28)*100% -> 0.48573401 | I28: =C28-(C28/2.8)-D28-E28-F28-G28 -> 2876.1693 | J28: =I28*$J$2 -> 69028.064
A29: ='Дашборд'!A30 -> 26 | B29: =(D29+E29+F29+G29)/(1-(1/2.8)-0.5) -> 7463.5694 | C29: ='Дашборд'!B30 -> 3501.0025 | D29: 550 | E29: ='Дашборд'!E30 -> 382.55753 | F29: ='Дашборд'!AH28/$F$2 -> 133.66667 | H29: =(I29/C29)*100% -> 0.33830889 | I29: =C29-(C29/2.8)-D29-E29-F29-G29 -> 1184.4202 | J29: =I29*$J$2 -> 28426.086
A30: ='Дашборд'!A31 -> 27 | B30: =(D30+E30+F30+G30)/(1-(1/2.8)-0.5) -> 7955.4959 | C30: ='Дашборд'!B31 -> 9880.7975 | D30: 550 | E30: ='Дашборд'!E31 -> 452.83275 | F30: ='Дашборд'!AH29/$F$2 -> 133.66667 | H30: =(I30/C30)*100% -> 0.52783612 | I30: =C30-(C30/2.8)-D30-E30-F30-G30 -> 5215.4418 | J30: =I30*$J$2 -> 125170.6
A31: ='Дашборд'!A32 -> 28 | B31: =(D31+E31+F31+G31)/(1-(1/2.8)-0.5) -> 8754.69 | C31: ='Дашборд'!B32 -> 7753.8329 | D31: =550+100 -> 650 | E31: ='Дашборд'!E32 -> 600.67 | F31: ='Дашборд'!AH30/$F$2 -> 0 | H31: =(I31/C31)*100% -> 0.48156014 | I31: =C31-(C31/2.8)-D31-E31-F31-G31 -> 3733.9368 | J31: =I31*$J$2 -> 89614.484
A32: ='Дашборд'!A33 -> 901 | B32: =(D32+E32+F32+G32)/(1-(1/2.8)-0.5) -> 38692.748 | C32: ='Дашборд'!B33 -> 15691.747 | D32: 330 | E32: ='Дашборд'!E33 -> 197.53538 | F32: ='Дашборд'!AH32/$F$2 -> 5000 | H32: =(I32/C32)*100% -> 0.29059965 | I32: =C32-(C32/2.8)-D32-E32-F32-G32 -> 4560.0162 | J32: =I32*$J$2 -> 109440.39
A33: ='Дашборд'!A34 -> 29 | B33: =(D33+E33+F33+G33)/(1-(1/2.8)-0.5) -> 7849.3319 | C33: ='Дашборд'!B34 -> 11686.439 | D33: 550 | E33: ='Дашборд'!E34 -> 431.9998 | F33: ='Дашборд'!AH31/$F$2 -> 139.33333 | H33: =(I33/C33)*100% -> 0.54690549 | I33: =C33-(C33/2.8)-D33-E33-F33-G33 -> 6391.3779 | J33: =I33*$J$2 -> 153393.07
A34: ='Дашборд'!A35 | B34: =(D34+E34+F34+G34)/(1-(1/2.8)-0.5) -> 0 | C34: ='Дашборд'!B35 | E34: ='Дашборд'!E35 | F34: ='Дашборд'!AH33/$F$2 -> 0 | H34: =(I34/C34)*100% -> #DIV/0! | I34: =C34-(C34/2.8)-D34-E34-F34-G34 -> 0 | J34: =I34*$J$2 -> 0
A35: ='Дашборд'!A36 | B35: =(D35+E35+F35+G35)/(1-(1/2.8)-0.5) -> 0 | C35: ='Дашборд'!B36 | E35: ='Дашборд'!E36 | F35: ='Дашборд'!AH34/$F$2 -> 0 | H35: =(I35/C35)*100% -> #DIV/0! | I35: =C35-(C35/2.8)-D35-E35-F35-G35 -> 0 | J35: =I35*$J$2 -> 0
A36: ='Дашборд'!A37 | B36: =(D36+E36+F36+G36)/(1-(1/2.8)-0.5) -> 0 | C36: ='Дашборд'!B37 | E36: ='Дашборд'!E37 | F36: ='Дашборд'!AH35/$F$2 -> 0 | H36: =(I36/C36)*100% -> #DIV/0! | I36: =C36-(C36/2.8)-D36-E36-F36-G36 -> 0 | J36: =I36*$J$2 -> 0
A37: ='Дашборд'!A38 | B37: =(D37+E37+F37+G37)/(1-(1/2.8)-0.5) -> 0 | C37: ='Дашборд'!B38 | E37: ='Дашборд'!E38 | F37: ='Дашборд'!AH36/$F$2 -> 0 | H37: =(I37/C37)*100% -> #DIV/0! | I37: =C37-(C37/2.8)-D37-E37-F37-G37 -> 0 | J37: =I37*$J$2 -> 0
A38: ='Дашборд'!A39 | B38: =(D38+E38+F38+G38)/(1-(1/2.8)-0.5) -> 0 | C38: ='Дашборд'!B39 | E38: ='Дашборд'!E39 | F38: ='Дашборд'!AH37/$F$2 -> 0 | H38: =(I38/C38)*100% -> #DIV/0! | I38: =C38-(C38/2.8)-D38-E38-F38-G38 -> 0 | J38: =I38*$J$2 -> 0
A39: ='Дашборд'!A40 | B39: =(D39+E39+F39+G39)/(1-(1/2.8)-0.5) -> 0 | C39: ='Дашборд'!B40 | E39: ='Дашборд'!E40 | F39: ='Дашборд'!AH38/$F$2 -> 0 | H39: =(I39/C39)*100% -> #DIV/0! | I39: =C39-(C39/2.8)-D39-E39-F39-G39 -> 0 | J39: =I39*$J$2 -> 0
A40: ='Дашборд'!A41 | B40: =(D40+E40+F40+G40)/(1-(1/2.8)-0.5) -> 0 | C40: ='Дашборд'!B41 | E40: ='Дашборд'!E41 | F40: ='Дашборд'!AH39/$F$2 -> 0 | H40: =(I40/C40)*100% -> #DIV/0! | I40: =C40-(C40/2.8)-D40-E40-F40-G40 -> 0 | J40: =I40*$J$2 -> 0
...

Sheet _service_dashboard_vm
A1: Период прошлый | B1: 01.07.2026 - 25.07.2026 | O1: метрика | P1: прошлый | Q1: текущий | R1: разница | S1: разница %
A2: Период текущий | B2: 01.08.2026 - 25.08.2026 | O2: СР. Выручка | P2: =SUM(B6:B1000) -> 246431.49 | Q2: =SUM(C6:C1000) -> 246879.15 | R2: =Q2-P2 -> 447.66772 | S2: =R2/(P2*100%) -> 0.0018166012
A3: Обновлено | B3: 46259.381 | O3: СР. Кол-во чеков | P3: =SUM(E6:E1000) -> 1304.3471 | Q3: =SUM(F6:F1000) -> 1299.811 | R3: =Q3-P3 -> -4.5361307 | S3: =R3/(P3*100%) -> -0.003477702
B4: СР. ВЫРУЧКА | D4: =SUM(D6:D1000) -> -0.76517981 | E4: СР. КОЛ-ВО ЧЕКОВ | G4: =SUM(G6:G1000) -> -1.284705 | H4: СР. СРЕДНИЙ ЧЕК | J4: =SUM(J6:J1000) -> 0.55883108 | K4: СПИСАНИЯ | M4: =SUM(M6:M1000) -> 4.1660626 | O4: СР. Средний чек | P4: =AVERAGE(H6:H1000) -> 171.1788 | Q4: =AVERAGE(I6:I1000) -> 185.52142 | R4: =Q4-P4 -> 14.342627 | S4: =R4/(P4*100%) -> 0.083787407
A5: Точка | B5: Прошлый | C5: Текущий | D5: % | E5: Прошлый | F5: Текущий | G5: % | H5: Прошлый | I5: Текущий | J5: % | K5: Прошлый | L5: Текущий | M5: % | N5: Активна | O5: Списания | P5: =SUM(K6:K1000) -> 267715.48 | Q5: =SUM(L6:L1000) -> 295159.88 | R5: =Q5-P5 -> 27444.4 | S5: =R5/(P5*100%) -> 0.10251331
A6: 0 | B6: 147 | C6: 192 | D6: 0.30612245 | E6: 1 | F6: 1 | G6: 0 | H6: 147 | I6: 192 | J6: 0.30612245 | K6: 0 | L6: 0 | N6: нет
A7: 1 | B7: 16880.844 | C7: 16373.466 | D7: -0.030056483 | E7: 102.27778 | F7: 97 | G7: -0.05160239 | H7: 165.42311 | I7: 168.81742 | J7: 0.020518961 | K7: 42733.01 | L7: 19386.01 | M7: -0.54634579 | N7: да
A8: 2 | B8: 5052.5889 | C8: 4317.1844 | D8: -0.14555004 | E8: 25.055556 | F8: 22.625 | G8: -0.097006652 | H8: 212.7486 | I8: 193.95464 | J8: -0.088338815 | K8: 2732.46 | L8: 4902.85 | M8: 0.79429891 | N8: да
A9: 3 | B9: 7932.37 | C9: 6819.225 | D9: -0.14032943 | E9: 35.8 | F9: 27.875 | G9: -0.22136872 | H9: 200.75378 | I9: 246.18072 | J9: 0.22628189 | K9: 3368.05 | L9: 13321.11 | M9: 2.9551402 | N9: да
A10: 4 | B10: 6476.7556 | C10: 5841.9562 | D10: -0.098011929 | E10: 21.666667 | F10: 21.0625 | G10: -0.027884615 | H10: 301.62883 | I10: 274.84151 | J10: -0.088808897 | K10: 53743.64 | L10: 63490.62 | M10: 0.18136062 | N10: да
A11: 5 | B11: 16444.243 | C11: 17278.991 | D11: 0.05076228 | E11: 79.388889 | F11: 82.125 | G11: 0.034464661 | H11: 207.54699 | I11: 212.99558 | J11: 0.02625232 | K11: 11892.77 | L11: 7012.55 | M11: -0.41035184 | N11: да
A12: 6 | B12: 11145.828 | C12: 13627.487 | D12: 0.22265362 | E12: 59.222222 | F12: 67.866667 | G12: 0.14596623 | H12: 188.48486 | I12: 203.60473 | J12: 0.08021797 | K12: 9008.75 | L12: 14149.55 | M12: 0.57064521 | N12: да
A13: 7 | B13: 7394.3667 | C13: 6334.56 | D13: -0.14332623 | E13: 39.5 | F13: 35.666667 | G13: -0.097046414 | H13: 188.10406 | I13: 176.28677 | J13: -0.06282315 | K13: 2715.03 | L13: 3117.88 | M13: 0.14837773 | N13: да
A14: 8 | B14: 6938.5222 | C14: 7337.0433 | D14: 0.057436021 | E14: 31.333333 | F14: 32.733333 | G14: 0.044680851 | H14: 222.30248 | I14: 224.51128 | J14: 0.0099360104 | K14: 8409.08 | L14: 1600.4 | M14: -0.80968192 | N14: да
A15: 9 | B15: 11186.183 | C15: 9748.8433 | D15: -0.12849244 | E15: 52.388889 | F15: 47.066667 | G15: -0.10159067 | H15: 214.14665 | I15: 207.42265 | J15: -0.031399019 | K15: 4049.89 | L15: 1456.81 | M15: -0.64028406 | N15: да
A16: 10 | B16: 10564.956 | C16: 7592.4667 | D16: -0.28135366 | E16: 63.055556 | F16: 48.2 | G16: -0.23559471 | H16: 167.1535 | I16: 156.87965 | J16: -0.06146355 | K16: 19679.94 | L16: 21956.3 | M16: 0.11566905 | N16: да
A17: 11 | B17: 0 | C17: 0 | E17: 0 | F17: 0 | H17: 0 | I17: 0 | K17: 0 | L17: 0 | N17: нет
A18: 12 | B18: 5559.1361 | C18: 6017.98 | D18: 0.082538704 | E18: 33.944444 | F18: 37.2 | G18: 0.095908347 | H18: 163.24682 | I18: 163.81079 | J18: 0.003454704 | K18: 3461.69 | L18: 1934.66 | M18: -0.44112269 | N18: да
A19: 13 | B19: 6343.775 | C19: 5823.6733 | D19: -0.081986147 | E19: 42.277778 | F19: 36.066667 | G19: -0.14691196 | H19: 149.31188 | I19: 161.39489 | J19: 0.080924643 | K19: 3875.57 | L19: 4249.72 | M19: 0.096540638 | N19: да
A20: 14 | B20: 11110.491 | C20: 10170.987 | D20: -0.084560043 | E20: 64.444444 | F20: 55.6875 | G20: -0.13588362 | H20: 172.60654 | I20: 184.0674 | J20: 0.066398754 | K20: 10102.09 | L20: 9869.35 | M20: -0.023038797 | N20: да
A21: 15 | B21: 8578.525 | C21: 8299.7133 | D21: -0.03250112 | E21: 45.944444 | F21: 47.333333 | G21: 0.030229746 | H21: 187.03881 | I21: 175.24655 | J21: -0.063047145 | K21: 5500.35 | L21: 8273.87 | M21: 0.50424428 | N21: да
A22: 16 | B22: 7906.5139 | C22: 7266.5406 | D22: -0.080942533 | E22: 39.388889 | F22: 35.0625 | G22: -0.1098378 | H22: 203.88829 | I22: 200.5734 | J22: -0.01625834 | K22: 4928.73 | L22: 3491.72 | M22: -0.29155787 | N22: да
A23: 17 | B23: 6578.1556 | C23: 6162.76 | D23: -0.063147725 | E23: 36.055556 | F23: 33.2 | G23: -0.079198767 | H23: 183.75187 | I23: 187.38869 | J23: 0.019792003 | K23: 7991.72 | L23: 6512.89 | M23: -0.18504527 | N23: да
A24: 18 | B24: 0 | C24: 6322.1 | E24: 0 | F24: 33.6 | H24: 0 | I24: 195.03724 | K24: 0 | L24: 6005.39 | N24: да
A25: 19 | B25: 6888.4667 | C25: 6922.72 | D25: 0.0049725628 | E25: 40.5 | F25: 41.266667 | G25: 0.018930041 | H25: 170.76227 | I25: 169.64295 | J25: -0.0065548326 | K25: 5186.97 | L25: 4801.87 | M25: -0.07424373 | N25: да
A26: 20 | B26: 16973.869 | C26: 13149.569 | D26: -0.22530518 | E26: 77.888889 | F26: 58.5 | G26: -0.2489301 | H26: 218.2799 | I26: 227.96209 | J26: 0.04435674 | K26: 9718 | L26: 26531.81 | M26: 1.7301718 | N26: да
A27: 21 | B27: 8048.8618 | C27: 8810.2253 | D27: 0.0945927 | E27: 40.294118 | F27: 40.6 | G27: 0.0075912409 | H27: 200.62658 | I27: 216.57749 | J27: 0.079505439 | K27: 3208.48 | L27: 4568.27 | M27: 0.42381128 | N27: да
A28: 22 | B28: 5974.0794 | C28: 6425.0821 | D28: 0.07549326 | E28: 39.588235 | F28: 41.142857 | G28: 0.039269794 | H28: 151.55568 | I28: 154.94889 | J28: 0.02238925 | K28: 9418.32 | L28: 10573.51 | M28: 0.12265351 | N28: да
A29: 23 | B29: 9269.5029 | C29: 9206.6967 | D29: -0.0067755817 | E29: 46.941176 | F29: 45.666667 | G29: -0.027151211 | H29: 198.69439 | I29: 188.35127 | J29: -0.052055426 | K29: 6662.52 | L29: 8336.8 | M29: 0.25129831 | N29: да
A30: 24 | B30: 6875.1278 | C30: 6917.6769 | D30: 0.0061888516 | E30: 41.444444 | F30: 38.230769 | G30: -0.077541761 | H30: 164.71984 | I30: 181.91781 | J30: 0.10440741 | K30: 13190.15 | L30: 7289 | M30: -0.44739067 | N30: да
A31: 25 | B31: 0 | C31: 5921.2846 | E31: 0 | F31: 36.615385 | H31: 0 | I31: 168.64737 | K31: 0 | L31: 9299.51 | N31: нет
A32: 26 | B32: 3815.7375 | C32: 4032.1538 | D32: 0.05671678 | E32: 22.3125 | F32: 23.846154 | G32: 0.068735186 | H32: 172.9265 | I32: 169.81178 | J32: -0.018011814 | K32: 4668.67 | L32: 4367.15 | M32: -0.064583704 | N32: да
A33: 27 | B33: 10723.4 | C33: 9391.3923 | D33: -0.12421505 | E33: 59.133333 | F33: 55.230769 | G33: -0.065996011 | H33: 181.71871 | I33: 169.73109 | J33: -0.065967966 | K33: 8923.96 | L33: 10637.68 | M33: 0.19203582 | N33: да
A34: 28 | B34: 6886.3429 | C34: 7437.7833 | D34: 0.080077406 | E34: 40.214286 | F34: 46.583333 | G34: 0.15837774 | H34: 170.76955 | I34: 160.17775 | J34: -0.062023908 | K34: 5584.47 | L34: 9421.33 | M34: 0.68705893 | N34: да
A35: 29 | B35: 11937.771 | C35: 9931.2292 | D35: -0.16808349 | E35: 61 | F35: 48.666667 | G35: -0.20218579 | H35: 195.82412 | I35: 204.81608 | J35: 0.045918537 | K35: 6484.66 | L35: 8601.27 | M35: 0.32640262 | N35: да
A36: 901 | B36: 12798.071 | C36: 13206.364 | D36: 0.031902635 | E36: 62.285714 | F36: 62.090909 | G36: -0.0031276063 | H36: 205.52807 | I36: 213.56562 | J36: 0.03910686 | K36: 476.51 | L36: 0 | M36: -1 | N36: да

Sheet Дашборд
A1: >12000 | B1: 9000-12000 | C1: 7000-9000 | D1: <7000 | E1: Точек | X1: Месяц | Y1: Списания | Z1: Выручка | AA1: % списаний | AF1: ИТОГ | AG1: Точка | AH1: Стоимость содержания
A2: 4 | B2: 7 | C2: 7 | D2: 12 | E2: 30 | X2: 46053 | Y2: 158849.28 | Z2: 5017742 | AA2: 0.031657522 | AF2: =SUM(AH2:AH1020) -> 232489 | AG2: 0 | AH2: 0
B3: Средние значения по точкам | I3: ФАКТ | J3: ПЛАН | K3: Отклонение | X3: 46081 | Y3: 237866.45 | Z3: 4999554 | AA3: 0.047577534 | AG3: 1 | AH3: 2300
A4: № точки | B4: Выручка ср.-я | C4: Чеков ср.-е | D4: Ср.-й чек | E4: Списания ср.-е | F4: Среднебудничная выручка на 1 точку | I4: =AVERAGE(B5:B1020) -> 8719.3432 | J4: 9500 | K4: =(I4-J4)/J4 -> -0.082174402 | X4: 46112 | Y4: =247373.84-29449 -> 217924.84 | Z4: 5556634 | AA4: 0.044518649 | AG4: 2 | AH4: 300
A5: 1 | B5: ='1'!D2 -> 17400.554 | C5: ='1'!G$2 -> 106.08387 | D5: ='1'!H$2 -> 165.12835 | E5: ='1'!I$2 -> 699.88813 | X5: 46142 | Y5: =452394.84-47916 -> 404478.84 | Z5: =6979185 -> 6979185 | AA5: 0.067673996 | AG5: 3 | AH5: 3892
A6: 2 | B6: ='2'!D2 -> 5056.7733 | C6: ='2'!G$2 -> 23.625806 | D6: ='2'!H$2 -> 219.14064 | E6: ='2'!I$2 -> 185.69216 | X6: 46173 | Y6: =369911.43-142159 -> 227752.43 | Z6: 7122430 | AA6: =Y6/(Z6/100%) -> 0.031976787 | AG6: 4
A7: 3 | B7: ='3'!D$2 -> 7694.3712 | C7: ='3'!G$2 -> 32 | D7: ='3'!H$2 -> 238.09568 | E7: ='3'!I$2 -> 673.63115 | X7: 46203 | Y7: =359696.35-110000 -> 249696.35 | Z7: 6644976 | AA7: =Y7/(Z7/100%) -> 0.037576712 | AG7: 5 | AH7: 300
A8: 4 | B8: ='4'!D$2-'4'!C2 -> 2941.4374 | C8: ='4'!G$2 -> 32.157895 | D8: ='4'!H$2 -> 248.86864 | E8: ='4'!I$2 -> 1248.4317 | X8: 46234 | Y8: 341983.18 | Z8: 7338851 | AA8: =Y8/(Z8/100%) -> 0.046599008 | AG8: 6 | AH8: 3638
A9: 5 | B9: ='5'!D$2 -> 14822.316 | C9: ='5'!G$2 -> 70.096774 | D9: ='5'!H$2 -> 212.75225 | E9: ='5'!I$2 -> 449.86747 | X9: 46258 | Y9: 295159.88 | AG9: 7 | AH9: 300
A10: 6 | B10: ='6'!D$2 -> 9760.7927 | C10: ='6'!G$2 -> 49.192053 | D10: ='6'!H$2 -> 201.51469 | E10: ='6'!I$2 -> 520.84796 | AG10: 8 | AH10: 5810
A11: 7 | B11: ='7'!D$2 -> 5577.0686 | C11: ='7'!G$2 -> 30.305785 | D11: ='7'!H$2 -> 184.06041 | E11: ='7'!I$2 -> 239.24305 | AG11: 9 | AH11: 9900
A12: 8 | B12: ='8'!D$2 -> 7437.8164 | C12: ='8'!G$2 -> 31.973684 | D12: ='8'!H$2 -> 238.04987 | E12: ='8'!I$2 -> 257.44539 | AG12: 10 | AH12: 3810
A13: 9 | B13: ='9'!D$2 -> 10341.419 | C13: ='9'!G$2 -> 49.058442 | D13: ='9'!H$2 -> 211.44077 | E13: ='9'!I$2 -> 207.56388 | AG13: 11
A14: 10 | B14: ='10'!D$2 -> 9886.613 | C14: ='10'!G$2 -> 59.243421 | D14: ='10'!H$2 -> 168.01002 | E14: ='10'!I$2 -> 563.05645 | AG14: 12 | AH14: 4800
A15: 11 | AG15: 13 | AH15: 4800
A16: 12 | B16: ='12'!D$2 -> 6144.2566 | C16: ='12'!G$2 -> 41.97351 | D16: ='12'!H$2 -> 148.29333 | E16: ='12'!I$2 -> 222.51589 | AG16: 14 | AH16: 6765
A17: 13 | B17: ='13'!D$2 -> 6274.8255 | C17: ='13'!G$2 -> 53.152318 | D17: ='13'!H$2 -> 126.24771 | E17: ='13'!I$2 -> 265.27927 | AG17: 15 | AH17: 2800
A18: 14 | B18: ='14'!D$2 -> 11786.44 | C18: ='14'!G$2 -> 67.631579 | D18: ='14'!H$2 -> 175.50604 | E18: ='14'!I$2 -> 345.51307 | AG18: 16 | AH18: 300
A19: 15 | B19: ='15'!D$2 -> 8637.9245 | C19: ='15'!G$2 -> 49.370861 | D19: ='15'!H$2 -> 176.16397 | E19: ='15'!I$2 -> 308.52669 | AG19: 17 | AH19: 7049
A20: 16 | B20: ='16'!D$2 -> 7918.1447 | C20: ='16'!G$2 -> 39.629139 | D20: ='16'!H$2 -> 200.7958 | E20: ='16'!I$2 -> 238.83135 | AG20: 18 | AH20: 300
A21: 17 | B21: ='17'!D$2 -> 6951.1225 | C21: ='17'!G$2 -> 38.019608 | D21: ='17'!H$2 -> 184.53327 | E21: ='17'!I$2 -> 437.35961 | AG21: 19 | AH21: 2239
A22: 18 | B22: ='18'!D$2 -> 6322.1 | C22: ='18'!G$2 -> 33.6 | D22: ='18'!H$2 -> 195.03724 | E22: ='18'!I$2 -> 839.36286 | AG22: 20 | AH22: 3606
A23: 19 | B23: ='19'!D$2 -> 6887.1429 | C23: ='19'!G$2 -> 39.965986 | D23: ='19'!H$2 -> 173.86633 | E23: ='19'!I$2 -> 299.13946 | AG23: 21 | AH23: 2180
A24: 20 | B24: ='20'!D$2 -> 15616.147 | C24: ='20'!G$2 -> 71.915033 | D24: ='20'!H$2 -> 217.79266 | E24: ='20'!I$2 -> 610.62811 | AG24: 22 | AH24: 2300
A25: 21 | B25: ='21'!D$2 -> 7178.7581 | C25: ='21'!G$2 -> 36.184932 | D25: ='21'!H$2 -> 197.87501 | E25: ='21'!I$2 -> 264.33801 | AG25: 23 | AH25: 2300
A26: 22 | B26: ='22'!D$2 -> 6456.0993 | C26: ='22'!G$2 -> 42.194444 | D26: ='22'!H$2 -> 153.67644 | E26: ='22'!I$2 -> 424.41945 | AG26: 24 | AH26: 300
A27: 23 | B27: ='23'!D$2 -> 9432.3562 | C27: ='23'!G$2 -> 49.8 | D27: ='23'!H$2 -> 189.4962 | E27: ='23'!I$2 -> 311.40757 | AG27: 25 | AH27: 300
A28: 24 | B28: ='24'!D$2 -> 7901.369 | C28: ='24'!G$2 -> 42.325926 | D28: ='24'!H$2 -> 183.87019 | E28: ='24'!I$2 -> 553.78833 | AG28: 26 | AH28: 4010
A29: 25 | B29: ='25'!D$2 -> 5921.2846 | C29: ='25'!G$2 -> 36.615385 | D29: ='25'!H$2 -> 168.64737 | E29: ='25'!I$2 -> 370.37077 | AG29: 27 | AH29: 4010
A30: 26 | B30: ='26'!D$2 -> 3501.0025 | C30: ='26'!G$2 -> 19.876543 | D30: ='26'!H$2 -> 178.63902 | E30: ='26'!I$2 -> 382.55753 | AG30: 28 | AH30: 0
A31: 27 | B31: ='27'!D$2 -> 9880.7975 | C31: ='27'!G$2 -> 58.25641 | D31: ='27'!H$2 -> 171.46891 | E31: ='27'!I$2 -> 452.83275 | AG31: 29 | AH31: 4180
A32: 28 | B32: ='28'!D$2 -> 7753.8329 | C32: ='28'!G$2 -> 46.164384 | D32: ='28'!H$2 -> 168.72576 | E32: ='28'!I$2 -> 600.67 | AG32: 901 | AH32: 150000
A33: 901 | B33: ='901'!D$2 -> 15691.747 | C33: ='901'!G$2 -> 74.936709 | D33: ='901'!H$2 -> 210.01242 | E33: ='901'!I$2 -> 197.53538
A34: 29 | B34: ='29'!D$2 -> 11686.439 | C34: ='29'!G$2 -> 60.319149 | D34: ='29'!H$2 -> 192.62704 | E34: ='29'!I$2 -> 431.9998

Sheet 0
A1: Точка | B1: 0 | C1: Дата запуска | E1: Тип точки | F1: офис | G1: Активна | H1: Нет | K1: Стоимость обслуживания | L1: Аренда | M1: Коммуналка | N1: Клининг
A2: Среднее | B2: 209.08333 | D2: 209.08333 | E2: 1.1666667 | G2: 1.1666667 | H2: 187 | K2: =SUM(L2:Q2) -> 0
A3: Дата | B3: $ QR-код | C3: $ Касса | D3: $ Итог | E3: Чеки QR | F3: Чеки Касса | G3: Чеки Итог | H3: Ср.-й чек | I3: Списания | J3: д/н
A4: 46256 | B4: 172 | D4: 172 | E4: 1 | G4: 1 | H4: 172 | J4: Сб
A5: 46249 | B5: 209.4 | D5: 209.4 | E5: 1 | G5: 1 | H5: 209.4 | J5: Сб
A6: 46237 | B6: 192 | D6: 192 | E6: 1 | G6: 1 | H6: 192 | J6: Пн
A7: 46231 | B7: 98 | D7: 98 | E7: 1 | G7: 1 | H7: 98 | J7: Вт
A8: 46230 | B8: 310 | D8: 310 | E8: 1 | G8: 1 | H8: 310 | J8: Пн
A9: 46221 | B9: 45 | D9: 45 | E9: 1 | G9: 1 | H9: 45 | J9: Сб
A10: 46220 | B10: 98 | D10: 98 | E10: 1 | G10: 1 | H10: 98 | J10: Пт
A11: 46219 | B11: 196 | D11: 196 | E11: 1 | G11: 1 | H11: 196 | J11: Чт
A12: 46198 | B12: 196 | D12: 196 | E12: 2 | G12: 2 | H12: 98 | J12: Чт
A13: 46186 | B13: 160 | D13: 160 | E13: 1 | G13: 1 | H13: 160 | J13: Сб
A14: 46183 | B14: 334 | D14: 334 | E14: 2 | G14: 2 | H14: 167 | J14: Ср
A15: 46180 | B15: 115 | D15: 115 | E15: 1 | G15: 1 | H15: 115 | J15: Вс
... A21: 46148 | B21: 309 | D21: 309 | E21: 1 | G21: 1 | H21: 309 | J21: Ср

Sheet 1
A1: Точка | B1: 1 | C1: Дата запуска | D1: 45901 | E1: Тип точки | F1: офис | G1: Активна | H1: Да | K1: Стоимость обслуживания | L1: Аренда | M1: Коммуналка | N1: Клининг
A2: Среднее | B2: 315.97778 | C2: 17345.513 | D2: 17400.554 | E2: 2 | F2: 105.73548 | G2: 106.08387 | H2: 165.12835 | I2: 699.88813 | K2: =SUM(L2:Q2) -> 2300 | L2: 2000 | M2: 0 | N2: 300
A3: Дата | B3: $ QR-код | C3: $ Касса | D3: $ Итог | E3: Чеки QR | F3: Чеки Касса | G3: Чеки Итог | H3: Ср.-й чек | I3: Списания | J3: д/н
A4: 46257 | B4: 240 | C4: 14075.5 | D4: 14315.5 | E4: 2 | F4: 74 | G4: 76 | H4: 188.36184 | I4: 1097.93 | J4: Вс
A5: 46256 | B5: 380 | C5: 20767.9 | D5: 21147.9 | E5: 4 | F5: 115 | G5: 119 | H5: 177.71345 | I5: 310.02 | J5: Сб
A6: 46255 | B6: 762 | C6: 12203.8 | D6: 12965.8 | E6: 3 | F6: 80 | G6: 83 | H6: 156.21446 | I6: 1132.32 | J6: Пт
A7: 46254 | B7: 845 | C7: 20099 | D7: 20944 | E7: 5 | F7: 109 | G7: 114 | H7: 183.7193 | I7: 111.72 | J7: Чт
A8: 46253 | B8: 229 | C8: 15487.3 | D8: 15716.3 | E8: 1 | F8: 97 | G8: 98 | H8: 160.37041 | I8: 1156.65 | J8: Ср
A9: 46252 | B9: 896 | C9: 12819 | D9: 13715 | E9: 6 | F9: 85 | G9: 91 | H9: 150.71429 | I9: 3079.87 | J9: Вт
A10: 46251 | B10: 740 | C10: 15340.2 | D10: 16080.2 | E10: 5 | F10: 87 | G10: 92 | H10: 174.78478 | I10: 415.18 | J10: Пн
A11: 46250 | B11: 971 | C11: 16874.6 | D11: 17845.6 | E11: 7 | F11: 105 | G11: 112 | H11: 159.33571 | I11: 3202.87 | J11: Вс
A12: 46249 | B12: 1096 | C12: 18017.75 | D12: 19113.75 | E12: 6 | F12: 97 | G12: 103 | H12: 185.57039 | I12: 0 | J12: Сб
A13: 46248 | B13: 205 | C13: 17215 | D13: 17420 | E13: 2 | F13: 106 | G13: 108 | H13: 161.2963 | I13: 248.77 | J13: Пт
A14: 46247 | C14: 15287.4 | D14: 15287.4 | F14: 102 | G14: 102 | H14: 149.87647 | I14: 99.76 | J14: Чт
A15: 46246 | C15: 13514.8 | D15: 13514.8 | F15: 83 | G15: 83 | H15: 162.82892 | I15: 116.88 | J15: Ср
A16: 46245 | C16: 16184.3 | D16: 16184.3 | F16: 105 | G16: 105 | H16: 154.13619 | I16: 259.42 | J16: Вт
A17: 46244 | C17: 16255.55 | D17: 16255.55 | F17: 90 | G17: 90 | H17: 180.61722 | I17: 848.55 | J17: Пн
A18: 46243 | C18: 13416.8 | D18: 13416.8 | F18: 90 | G18: 90 | H18: 149.07556 | I18: 2169.68 | J18: Вс
A19: 46242 | C19: 24837.5 | D19: 24837.5 | F19: 135 | G19: 135 | H19: 183.98148 | I19: 72.44 | J19: Сб
A20: 46241 | C20: 16756.8 | D20: 16756.8 | F20: 108 | G20: 108 | H20: 155.15556 | I20: 508.85 | J20: Пт
A21: 46240 | C21: 22246.4 | D21: 22246.4 | F21: 116 | G21: 116 | H21: 191.77931 | I21: 349.86 | J21: Чт
A22: 46239 | C22: 18712 | D22: 18712 | F22: 101 | G22: 101 | H22: 185.26733 | I22: 295.65 | J22: Ср
A23: 46238 | C23: 17980.6 | D23: 17980.6 | F23: 103 | G23: 103 | H23: 174.56893 | I23: 1028.2 | J23: Вт
A24: 46237 | C24: 15012.5 | D24: 15012.5 | F24: 89 | G24: 89 | H24: 168.67978 | I24: 373.09 | J24: Пн
A25: 46236 | C25: 16361.4 | D25: 16361.4 | F25: 86 | G25: 86 | H25: 190.24884 | I25: 1655.78 | J25: Вс
... A43: 46218 | C43: 15856.8 | D43: 15856.8 | F43: 85 | G43: 85 | H43: 186.55059 | I43: 866.2 | J43: Ср
A44: 46217 | B44: 25 | C44: 13966.8 | D44: 13991.8 | E44: 1 | F44: 96 | G44: 97 | H44: 144.24536 | I44: 6588.86 | J44: Вт
A45: 46216 | C45: 14774.9 | D45: 14774.9 | F45: 94 | G45: 94 | H45: 157.17979 | I45: 262.67 | J45: Пн
A46: 46215 | C46: 17918.2 | D46: 17918.2 | F46: 115 | G46: 115 | H46: 155.81043 | I46: 2176.97 | J46: Вс
A47: 46214 | C47: 22378.2 | D47: 22378.2 | F47: 135 | G47: 135 | H47: 165.76444 | I47: 12716.75 | J47: Сб
A48: 46213 | C48: 18406.8 | D48: 18406.8 | F48: 119 | G48: 119 | H48: 154.67899 | I48: 371.98 | J48: Пт
A49: 46212 | B49: 97 | C49: 19215.6 | D49: 19312.6 | E49: 1 | F49: 105 | G49: 106 | H49: 182.19434 | I49: 252.36 | J49: Чт
A50: 46211 | C50: 14788.8 | D50: 14788.8 | F50: 87 | G50: 87 | H50: 169.98621 | I50: 529.48 | J50: Ср
A51: 46210 | C51: 16779.4 | D51: 16779.4 | F51: 96 | G51: 96 | H51: 174.78542 | I51: 0 | J51: Вт
A52: 46209 | B52: 210 | C52: 14279.4 | D52: 14489.4 | E52: 1 | F52: 85 | G52: 86 | H52: 168.4814 | I52: 171.66 | J52: Пн
A53: 46208 | C53: 17053.4 | D53: 17053.4 | F53: 110 | G53: 110 | H53: 155.03091 | I53: 958.25 | J53: Вс
A54: 46207 | C54: 24853.6 | D54: 24853.6 | F54: 151 | G54: 151 | H54: 164.59338 | I54: 221.91 | J54: Сб
A55: 46206 | C55: 17103.2 | D55: 17103.2 | F55: 117 | G55: 117 | H55: 146.1812 | I55: 79.31 | J55: Пт
A56: 46205 | C56: 19833.5 | D56: 19833.5 | F56: 128 | G56: 128 | H56: 154.94922 | I56: 907.49 | J56: Чт
A57: 46204 | C57: 14773.15 | D57: 14773.15 | F57: 97 | G57: 97 | H57: 152.30052 | I57: 143.23 | J57: Ср
...

Sheet 2
A1: Точка | B1: 2 | C1: Дата запуска | D1: 45914 | E1: Тип точки | F1: офис | G1: Активна | H1: Да | K1: Стоимость обслуживания | L1: Аренда | M1: Коммуналка | N1: Клининг
A2: Среднее | B2: 723.5 | C2: 5038.1023 | D2: 5056.7733 | E2: 1.25 | F2: 23.593548 | G2: 23.625806 | H2: 219.14064 | I2: 185.69216 | K2: =SUM(L2:Q2) -> 300 | L2: 0 | M2: 0 | N2: 300
A3: Дата | B3: $ QR-код | C3: $ Касса | D3: $ Итог | E3: Чеки QR | F3: Чеки Касса | G3: Чеки Итог | H3: Ср.-й чек | I3: Списания | J3: д/н
A4: 46257 | C4: 0 | F4: 0 | I4: 160.39 | J4: Вс
A5: 46256 | C5: 532.2 | D5: 532.2 | F5: 4 | G5: 4 | H5: 133.05 | I5: 54.95 | J5: Сб
A6: 46255 | C6: 3271.4 | D6: 3271.4 | F6: 14 | G6: 14 | H6: 233.67143 | I6: 0 | J6: Пт
A7: 46254 | C7: 4403.6 | D7: 4403.6 | F7: 31 | G7: 31 | H7: 142.05161 | I7: 0 | J7: Чт
A8: 46253 | C8: 3454 | D8: 3454 | F8: 20 | G8: 20 | H8: 172.7 | I8: 40.98 | J8: Ср
A9: 46252 | C9: 5368.4 | D9: 5368.4 | F9: 26 | G9: 26 | H9: 206.47692 | I9: 0 | J9: Вт
A10: 46251 | C10: 6193 | D10: 6193 | F10: 24 | G10: 24 | H10: 258.04167 | I10: 35.95 | J10: Пн
A11: 46250 | C11: 523.9 | D11: 523.9 | F11: 10 | G11: 10 | H11: 52.39 | I11: 517.53 | J11: Вс
A12: 46249 | C12: 562.8 | D12: 562.8 | F12: 3 | G12: 3 | H12: 187.6 | I12: 0 | J12: Сб
A13: 46248 | C13: 5104.75 | D13: 5104.75 | F13: 20 | G13: 20 | H13: 255.2375 | I13: 0 | J13: Пт
A14: 46247 | C14: 3640 | D14: 3640 | F14: 25 | G14: 25 | H14: 145.6 | I14: 108.82 | J14: Чт
A15: 46246 | C15: 4373.3 | D15: 4373.3 | F15: 23 | G15: 23 | H15: 190.14348 | I15: 71.58 | J15: Ср
A16: 46245 | C16: 3286.1 | D16: 3286.1 | F16: 29 | G16: 29 | H16: 113.31379 | I16: 91.54 | J16: Вт
... A24: 46237 | C24: 4836 | D24: 4836 | F24: 22 | G24: 22 | H24: 219.81818 | I24: 0 | J24: Пн
A25: 46236 | C25: 0 | F25: 8 | G25: 8 | H25: 0 | I25: 621.83 | J25: Вс
A26: 46235 | C26: 502.8 | D26: 502.8 | F26: 2 | G26: 2 | H26: 251.4 | I26: 271.01 | J26: Сб
A27: 46234 | C27: 4417.2 | D27: 4417.2 | F27: 17 | G27: 17 | H27: 259.83529 | I27: 85.74 | J27: Пт
A28: 46233 | C28: 3407.2 | D28: 3407.2 | F28: 24 | G28: 24 | H28: 141.96667 | I28: 0 | J28: Чт
A29: 46232 | C29: 5629 | D29: 5629 | F29: 26 | G29: 26 | H29: 216.5 | I29: 139.72 | J29: Ср
A30: 46231 | C30: 6264 | D30: 6264 | F30: 30 | G30: 30 | H30: 208.8 | I30: 0 | J30: Вт
A31: 46230 | C31: 4579 | D31: 4579 | F31: 17 | G31: 17 | H31: 269.35294 | I31: 299.38 | J31: Пн
A32: 46229 | C32: 402.4 | D32: 402.4 | F32: 5 | G32: 5 | H32: 80.48 | I32: 739.62 | J32: Вс
A33: 46228 | C33: 1098.6 | D33: 1098.6 | F33: 5 | G33: 5 | H33: 219.72 | I33: 187.3 | J33: Сб
A34: 46227 | C34: 4303.6 | D34: 4303.6 | F34: 20 | G34: 20 | H34: 215.18 | I34: 837.01 | J34: Пт
A35: 46226 | C35: 3866.4 | D35: 3866.4 | F35: 19 | G35: 19 | H35: 203.49474 | I35: 91.1 | J35: Чт
A36: 46225 | C36: 4779.5 | D36: 4779.5 | F36: 26 | G36: 26 | H36: 183.82692 | I36: 53.43 | J36: Ср
A37: 46224 | C37: 4742 | D37: 4742 | F37: 29 | G37: 29 | H37: 163.51724 | I37: 0 | J37: Вт
... A45: 46216 | C45: 6137.5 | D45: 6137.5 | F45: 29 | G45: 29 | H45: 211.63793 | I45: 0 | J45: Пн
A46: 46215 | C46: 0 | F46: 2 | G46: 2 | H46: 0 | I46: 82.72 | J46: Вс
A47: 46214 | C47: 198.8 | D47: 198.8 | F47: 2 | G47: 2 | H47: 99.4 | I47: 26.47 | J47: Сб
A48: 46213 | C48: 2879.4 | D48: 2879.4 | F48: 7 | G48: 7 | H48: 411.34286 | I48: 0 | J48: Пт
A49: 46212 | C49: 6221.4 | D49: 6221.4 | F49: 30 | G49: 30 | H49: 207.38 | I49: 0 | J49: Чт
A50: 46211 | C50: 6544 | D50: 6544 | F50: 31 | G50: 31 | H50: 211.09677 | I50: 38.22 | J50: Ср
A51: 46210 | C51: 5593.8 | D51: 5593.8 | F51: 28 | G51: 28 | H51: 199.77857 | I51: 0 | J51: Вт
A52: 46209 | C52: 3740 | D52: 3740 | F52: 22 | G52: 22 | H52: 170 | I52: 75.4 | J52: Пн
A53: 46208 | C53: 452.8 | D53: 452.8 | F53: 11 | G53: 11 | H53: 41.163636 | I53: 4 | J53: Вс
A54: 46207 | C54: 98 | D54: 98 | F54: 1 | G54: 1 | H54: 98 | I54: 0 | J54: Сб
...

Sheet 3
A1: Точка | B1: 3 | C1: Дата запуска | D1: 46224 | E1: Тип точки | F1: медицина | G1: Активна | H1: Да | K1: Стоимость обслуживания | L1: Аренда | M1: Коммуналка | N1: Клининг
A2: Среднее | C2: 7694.3712 | D2: 7694.3712 | F2: 32 | G2: 32 | H2: 238.09568 | I2: 673.63115 | K2: =SUM(L2:Q2) -> 3892 | L2: 2013 | M2: 1579 | N2: 300
A3: Дата | B3: $ QR-код | C3: $ Касса | D3: $ Итог | E3: Чеки QR | F3: Чеки Касса | G3: Чеки Итог | H3: Ср.-й чек | I3: Списания | J3: д/н
A4: 46257 | C4: 1237 | D4: 1237 | F4: 5 | G4: 5 | H4: 247.4 | I4: 578.09 | J4: Вс
A5: 46256 | C5: 1639.6 | D5: 1639.6 | F5: 3 | G5: 3 | H5: 546.53333 | I5: 0 | J5: Сб
A6: 46255 | C6: 5839.6 | D6: 5839.6 | F6: 27 | G6: 27 | H6: 216.28148 | I6: 1486.86 | J6: Пт
A7: 46254 | C7: 6965.2 | D7: 6965.2 | F7: 23 | G7: 23 | H7: 302.83478 | I7: 381.51 | J7: Чт
A8: 46253 | C8: 4759.2 | D8: 4759.2 | F8: 21 | G8: 21 | H8: 226.62857 | I8: 348.74 | J8: Ср
A9: 46252 | C9: 5561.2 | D9: 5561.2 | F9: 23 | G9: 23 | H9: 241.7913 | I9: 625.92 | J9: Вт
A10: 46251 | C10: 7333.5 | D10: 7333.5 | F10: 25 | G10: 25 | H10: 293.34 | I10: 267.32 | J10: Пн
A11: 46250 | C11: 1857.6 | D11: 1857.6 | F11: 8 | G11: 8 | H11: 232.2 | I11: 766.13 | J11: Вс
A12: 46249 | C12: 2223.2 | D12: 2223.2 | F12: 5 | G12: 5 | H12: 444.64 | I12: 0 | J12: Сб
A13: 46248 | C13: 9637 | D13: 9637 | F13: 33 | G13: 33 | H13: 292.0303 | I13: 780.64 | J13: Пт
A14: 46247 | C14: 7036.6 | D14: 7036.6 | F14: 30 | G14: 30 | H14: 234.55333 | I14: 180.94 | J14: Чт
A15: 46246 | C15: 7057.4 | D15: 7057.4 | F15: 33 | G15: 33 | H15: 213.86061 | I15: 467.41 | J15: Ср
... A38: 46223 | C38: 287 | D38: 287 | F38: 3 | G38: 3 | H38: 95.666667 | I38: 0 | J38: Пн
J40: Вт
J41: Пн
J42: Вс
J43: Сб
J44: Пт
J45: Чт
J46: Ср
J47: Вт
J48: Пн
J49: Вс
J50: Сб
J51: Пт
... J63: Сб
J64: Пт | L64: ТОП-3 Целевой аудитории
J65: Чт | L65: пол | M65: возраст | N65: % присутствия | P65: кол-во уникальных гостей
J66: Ср | L66: женщины
J67: Вт | L67: мужчины
J68: Пн | L68: мужчины
J69: Вс
J70: Сб | L70: График работы | M70: дней в неделю | N70: часы работы
J71: Пт | M71: 5 | N71: 08:00-17:00
J72: Чт
J73: Ср
J74: Вт
...

Sheet 4
A1: Точка | B1: 4 | C1: Дата запуска | D1: 45139 | E1: Тип точки | F1: завод | G1: Активна | H1: Да | K1: Стоимость обслуживания | L1: Аренда | M1: Коммуналка | N1: Клининг | P1: мерчант | Q1: QR мерч
A2: Среднее | B2: 3209.3308 | C2: 4849.0342 | D2: 7790.4716 | E2: 10.901408 | F2: 21.688312 | G2: 32.157895 | H2: 248.86864 | I2: 1248.4317 | K2: =SUM(L2:Q2) -> 4692 | L2: 4392 | M2: 0 | N2: 300
A3: Дата | B3: $ QR-код | C3: $ Касса | D3: $ Итог | E3: Чеки QR | F3: Чеки Касса | G3: Чеки Итог | H3: Ср.-й чек | I3: Списания | J3: д/н | P3: 33978529 | Q3: 33978530
A4: 46257 | B4: 1879.2 | C4: 0 | D4: 1879.2 | E4: 9 | F4: 0 | G4: 9 | H4: 208.8 | I4: 2842 | J4: Вс
A5: 46256 | B5: 4499.4 | C5: 0 | D5: 4499.4 | E5: 17 | F5: 0 | G5: 17 | H5: 264.67059 | I5: 2958.69 | J5: Сб
A6: 46255 | B6: 8751 | C6: 0 | D6: 8751 | E6: 20 | F6: 0 | G6: 20 | H6: 437.55 | I6: 1589.61 | J6: Пт
A7: 46254 | B7: 5667 | C7: 0 | D7: 5667 | E7: 19 | F7: 0 | G7: 19 | H7: 298.26316 | I7: 1321.49 | J7: Чт
A8: 46253 | B8: 5452.8 | C8: 0 | D8: 5452.8 | E8: 26 | F8: 0 | G8: 26 | H8: 209.72308 | I8: 2005.45 | J8: Ср
A9: 46252 | B9: 6011.8 | C9: 0 | D9: 6011.8 | E9: 25 | F9: 0 | G9: 25 | H9: 240.472 | I9: 14731.39 | J9: Вт
A10: 46251 | B10: 5478 | D10: 5478 | E10: 24 | G10: 24 | H10: 228.25 | J10: Пн
A11: 46250 | B11: 2360 | C11: 0 | D11: 2360 | E11: 11 | F11: 0 | G11: 11 | H11: 214.54545 | I11: 121.76 | J11: Вс
A12: 46249 | B12: 3765.8 | D12: 3765.8 | E12: 15 | G12: 15 | H12: 251.05333 | J12: Сб
A13: 46248 | B13: 10528.8 | C13: 0 | D13: 10528.8 | E13: 29 | F13: 0 | G13: 29 | H13: 363.06207 | I13: 135.43 | J13: Пт
A14: 46247 | B14: 5216.5 | C14: 0 | D14: 5216.5 | E14: 21 | F14: 0 | G14: 21 | H14: 248.40476 | I14: 98.57 | J14: Чт
A15: 46246 | B15: 4527 | C15: 0 | D15: 4527 | E15: 21 | F15: 0 | G15: 21 | H15: 215.57143 | I15: 222.83 | J15: Ср
A16: 46245 | B16: =26104-18803 -> 7301 | C16: 0 | D16: 7301 | E16: 25 | F16: 0 | G16: 25 | H16: 292.04 | I16: 3753.01 | J16: Вт
A17: 46244 | B17: 3414 | C17: 0 | D17: 3414 | E17: 18 | F17: 0 | G17: 18 | H17: 189.66667 | I17: 4154 | J17: Пн
A18: 46243 | B18: 4474 | C18: 0 | D18: 4474 | E18: 10 | F18: 0 | G18: 10 | H18: 447.4 | I18: 3409.25 | J18: Вс
A19: 46242 | B19: 3759.4 | C19: 0 | D19: 3759.4 | E19: 17 | F19: 0 | G19: 17 | H19: 221.14118 | I19: 2344.65 | J19: Сб
A20: 46241 | B20: 5099 | C20: 0 | D20: 5099 | E20: 20 | F20: 0 | G20: 20 | H20: 254.95 | I20: 2188.86 | J20: Пт
A21: 46240 | B21: 5026.4 | C21: 0 | D21: 5026.4 | E21: 19 | F21: 0 | G21: 19 | H21: 264.54737 | I21: 1857.02 | J21: Чт
A22: 46239 | B22: 4816 | C22: 0 | D22: 4816 | E22: 16 | F22: 0 | G22: 16 | H22: 301 | I22: 2813.02 | J22: Ср
A23: 46238 | B23: 2171 | C23: 0 | D23: 2171 | E23: 10 | F23: 0 | G23: 10 | H23: 217.1 | I23: 2068.4 | J23: Вт
A24: 46237 | B24: 8447 | C24: 0 | D24: 8447 | E24: 22 | F24: 0 | G24: 22 | H24: 383.95455 | I24: 3800.36 | J24: Пн
A25: 46236 | B25: 2371 | C25: 0 | D25: 2371 | E25: 10 | F25: 0 | G25: 10 | H25: 237.1 | I25: 4038.67 | J25: Вс
A26: 46235 | B26: 1439 | C26: 0 | D26: 1439 | E26: 3 | F26: 0 | G26: 3 | H26: 479.66667 | I26: 2883.09 | J26: Сб
A27: 46234 | B27: 2818 | C27: 0 | D27: 2818 | E27: 12 | F27: 0 | G27: 12 | H27: 234.83333 | I27: 1314.87 | J27: Пт
A28: 46233 | B28: 5089 | C28: 0 | D28: 5089 | E28: 15 | F28: 0 | G28: 15 | H28: 339.26667 | I28: 1451.66 | J28: Чт
... A54: 46207 | B54: 4685.2 | C54: 0 | D54: 4685.2 | E54: 16 | F54: 0 | G54: 16 | H54: 292.825 | I54: 2931.32 | J54: Сб
A55: 46206 | B55: 8974 | C55: 0 | D55: 8974 | F55: 0 | I55: 1223.99 | J55: Пт
A56: 46205 | B56: 6378 | C56: 0 | D56: 6378 | F56: 0 | I56: 1413.58 | J56: Чт
A57: 46204 | B57: 5024 | C57: 0 | D57: 5024 | F57: 0 | I57: 548.49 | J57: Ср
A58: 46203 | B58: 7787 | C58: 0 | D58: 7787 | F58: 0 | I58: 1009.61 | J58: Вт
A59: 46202 | B59: 6067 | C59: 0 | D59: 6067 | E59: 9 | F59: 0 | G59: 9 | H59: 674.11111 | I59: 1220.22 | J59: Пн
A60: 46201 | B60: 4838 | C60: 0 | D60: 4838 | E60: 23 | F60: 0 | G60: 23 | H60: 210.34783 | I60: 802.81 | J60: Вс
A61: 46200 | B61: 2008.9 | C61: 3156.2 | D61: 5165.1 | E61: 12 | F61: 12 | G61: 24 | H61: 215.2125 | I61: 1300.36 | J61: Сб
A62: 46199 | B62: 396 | C62: 8029.7 | D62: 8425.7 | E62: 4 | F62: 37 | G62: 41 | H62: 205.50488 | I62: 1331.46 | J62: Пт
A63: 46198 | B63: 476 | C63: 3777.2 | D63: 4253.2 | E63: 2 | F63: 21 | G63: 23 | H63: 184.92174 | I63: 831.69 | J63: Чт
A64: 46197 | B64: 800 | C64: 6042.5 | D64: 6842.5 | E64: 5 | F64: 32 | G64: 37 | H64: 184.93243 | I64: 418.78 | J64: Ср | L64: ТОП-3 Целевой аудитории
A65: 46196 | B65: 885 | C65: 6180 | D65: 7065 | E65: 4 | F65: 30 | G65: 34 | H65: 207.79412 | I65: 168.85 | J65: Вт | L65: пол | M65: возраст | N65: % присутствия | P65: кол-во уникальных гостей
...

Sheet 5
A1: Точка | B1: 5 | C1: Дата запуска | D1: 45901 | E1: Тип точки | F1: завод | G1: Активна | H1: Да | K1: Стоимость обслуживания | L1: Аренда | M1: Коммуналка | N1: Клининг
A2: Среднее | B2: 2236.1402 | C2: 13437.485 | D2: 14822.316 | E2: 10.137255 | F2: 63.837662 | G2: 70.096774 | H2: 212.75225 | I2: 449.86747 | K2: =SUM(L2:Q2) -> 300 | M2: 0 | N2: 300
A3: Дата | B3: $ QR-код | C3: $ Касса | D3: $ Итог | E3: Чеки QR | F3: Чеки Касса | G3: Чеки Итог | H3: Ср.-й чек | I3: Списания | J3: д/н
A4: 46257 | C4: 1499.4 | D4: 1499.4 | F4: 5 | G4: 5 | H4: 299.88 | I4: 692.33 | J4: Вс
A5: 46256 | C5: 702.2 | D5: 702.2 | F5: 4 | G5: 4 | H5: 175.55 | I5: 439.03 | J5: Сб
A6: 46255 | B6: 50 | C6: 14525.4 | D6: 14575.4 | E6: 1 | F6: 68 | G6: 69 | H6: 211.23768 | I6: 27.48 | J6: Пт
A7: 46254 | B7: 680 | C7: 22717.4 | D7: 23397.4 | E7: 5 | F7: 105 | G7: 110 | H7: 212.70364 | I7: 202.36 | J7: Чт
A8: 46253 | B8: 25 | C8: 18388 | D8: 18413 | E8: 1 | F8: 89 | G8: 90 | H8: 204.58889 | I8: 335.88 | J8: Ср
A9: 46252 | B9: 255 | C9: 17962.6 | D9: 18217.6 | E9: 3 | F9: 85 | G9: 88 | H9: 207.01818 | I9: 277.81 | J9: Вт
A10: 46251 | B10: 105 | C10: 16093.6 | D10: 16198.6 | E10: 2 | F10: 75 | G10: 77 | H10: 210.37143 | I10: 0 | J10: Пн
A11: 46250 | B11: 728.2 | C11: 4259 | D11: 4987.2 | E11: 3 | F11: 24 | G11: 27 | H11: 184.71111 | I11: 49.02 | J11: Вс
A12: 46249 | C12: 2696.4 | D12: 2696.4 | F12: 17 | G12: 17 | H12: 158.61176 | I12: 0 | J12: Сб
A13: 46248 | B13: 368 | C13: 15752 | D13: 16120 | E13: 5 | F13: 71 | G13: 76 | H13: 212.10526 | I13: 217.99 | J13: Пт
A14: 46247 | B14: 105 | C14: 17832.4 | D14: 17937.4 | E14: 1 | F14: 95 | G14: 96 | H14: 186.84792 | I14: 0 | J14: Чт
A15: 46246 | B15: 731 | C15: 19338.35 | D15: 20069.35 | E15: 5 | F15: 90 | G15: 95 | H15: 211.25632 | I15: 35.8 | J15: Ср
A16: 46245 | B16: 669 | C16: 17499.1 | D16: 18168.1 | E16: 5 | F16: 86 | G16: 91 | H16: 199.64945 | I16: 548.74 | J16: Вт
A17: 46244 | B17: 2825.55 | C17: 15726 | D17: 18551.55 | E17: 9 | F17: 79 | G17: 88 | H17: 210.81307 | I17: 1079.33 | J17: Пн
A18: 46243 | B18: 100 | C18: 357.4 | D18: 457.4 | E18: 1 | F18: 2 | G18: 3 | H18: 152.46667 | I18: 1323.52 | J18: Вс
A19: 46242 | B19: 90 | C19: 2225.6 | D19: 2315.6 | E19: 1 | F19: 18 | G19: 19 | H19: 121.87368 | I19: 495.49 | J19: Сб
A20: 46241 | B20: 4792 | C20: 14155.15 | D20: 18947.15 | E20: 17 | F20: 66 | G20: 83 | H20: 228.27892 | I20: 198.21 | J20: Пт
A21: 46240 | B21: 560 | C21: 21091.3 | D21: 21651.3 | E21: 2 | F21: 101 | G21: 103 | H21: 210.2068 | I21: 130.52 | J21: Чт
A22: 46239 | B22: 644 | C22: 16390.15 | D22: 17034.15 | E22: 5 | F22: 69 | G22: 74 | H22: 230.19122 | I22: 0 | J22: Ср
A23: 46238 | B23: 276 | C23: 16226.6 | D23: 16502.6 | E23: 3 | F23: 73 | G23: 76 | H23: 217.13947 | I23: 0 | J23: Вт
A24: 46237 | C24: 19448.25 | D24: 19448.25 | F24: 93 | G24: 93 | H24: 209.12097 | I24: 98.92 | J24: Пн
A25: 46236 | C25: 1407.4 | D25: 1407.4 | F25: 9 | G25: 9 | H25: 156.37778 | I25: 690.38 | J25: Вс
A26: 46235 | C26: 2973.4 | D26: 2973.4 | F26: 18 | G26: 18 | H26: 165.18889 | I26: 169.74 | J26: Сб
A27: 46234 | B27: 578 | C27: 18599.8 | D27: 19177.8 | E27: 3 | F27: 90 | G27: 93 | H27: 206.2129 | I27: 598.02 | J27: Пт
A28: 46233 | C28: 20723.6 | D28: 20723.6 | F28: 94 | G28: 94 | H28: 220.46383 | I28: 490.89 | J28: Чт
A29: 46232 | B29: 360 | C29: 19706.7 | D29: 20066.7 | E29: 2 | F29: 88 | G29: 90 | H29: 222.96333 | I29: 224.65 | J29: Ср
A30: 46231 | B30: 819 | C30: 14920 | D30: 15739 | E30: 7 | F30: 65 | G30: 72 | H30: 218.59722 | I30: 0 | J30: Вт
A31: 46230 | B31: 200 | C31: 21594 | D31: 21794 | E31: 2 | F31: 102 | G31: 104 | H31: 209.55769 | I31: 87.73 | J31: Пн
A32: 46229 | B32: 80 | C32: 2482 | D32: 2562 | E32: 1 | F32: 13 | G32: 14 | H32: 183 | I32: 423.76 | J32: Вс
A33: 46228 | B33: 85 | C33: 946.6 | D33: 1031.6 | E33: 1 | F33: 10 | G33: 11 | H33: 93.781818 | I33: 414.43 | J33: Сб
A34: 46227 | B34: 839 | C34: 17740.2 | D34: 18579.2 | E34: 7 | F34: 84 | G34: 91 | H34: 204.16703 | I34: 86 | J34: Пт
A35: 46226 | B35: 555 | C35: 20915.15 | D35: 21470.15 | E35: 6 | F35: 97 | G35: 103 | H35: 208.44806 | I35: 332.94 | J35: Чт
A36: 46225 | B36: 1018 | C36: 16095.6 | D36: 17113.6 | E36: 5 | F36: 79 | G36: 84 | H36: 203.73333 | I36: 497.58 | J36: Ср
A37: 46224 | B37: 587 | C37: 13777.2 | D37: 14364.2 | E37: 4 | F37: 71 | G37: 75 | H37: 191.52267 | I37: 540.34 | J37: Вт
A38: 46223 | B38: 90 | C38: 14798.2 | D38: 14888.2 | E38: 1 | F38: 81 | G38: 82 | H38: 181.56341 | I38: 950.98 | J38: Пн
A39: 46222 | C39: 1757.8 | D39: 1757.8 | F39: 5 | G39: 5 | H39: 351.56 | I39: 683.44 | J39: Вс
A40: 46221 | C40: 716.2 | D40: 716.2 | F40: 3 | G40: 3 | H40: 238.73333 | I40: 716.4 | J40: Сб
...

Sheet 6
A1: Точка | B1: 6 | C1: Дата запуска | D1: 45917 | E1: Тип точки | F1: завод | G1: Активна | H1: Да | K1: Стоимость обслуживания | L1: Аренда | M1: Коммуналка | N1: Клининг
A2: Среднее | B2: 650.26667 | C2: 9606.7375 | D2: 9760.7927 | E2: 1.4761905 | F2: 48.664474 | G2: 49.192053 | H2: 201.51469 | I2: 520.84796 | K2: =SUM(L2:Q2) -> 3638 | L2: 3338 | M2: 0 | N2: 300
A3: Дата | B3: $ QR-код | C3: $ Касса | D3: $ Итог | E3: Чеки QR | F3: Чеки Касса | G3: Чеки Итог | H3: Ср.-й чек | I3: Списания | J3: д/н
A4: 46257 | C4: 3943.8 | D4: 3943.8 | F4: 28 | G4: 28 | H4: 140.85 | I4: 258.12 | J4: Вс
A5: 46256 | C5: 4134.6 | D5: 4134.6 | F5: 36 | G5: 36 | H5: 114.85 | I5: 255.04 | J5: Сб
A6: 46255 | C6: 14426.4 | D6: 14426.4 | F6: 85 | G6: 85 | H6: 169.72235 | I6: 185.63 | J6: Пт
A7: 46254 | C7: 15454.8 | D7: 15454.8 | F7: 75 | G7: 75 | H7: 206.064 | I7: 96.04 | J7: Чт
A8: 46253 | C8: 15485.7 | D8: 15485.7 | F8: 88 | G8: 88 | H8: 175.97386 | I8: 516.25 | J8: Ср
A9: 46252 | C9: 15523.4 | D9: 15523.4 | F9: 85 | G9: 85 | H9: 182.62824 | I9: 2019.46 | J9: Вт
A10: 46251 | C10: 13468 | D10: 13468 | F10: 63 | G10: 63 | H10: 213.77778 | I10: 0 | J10: Пн
A11: 46250 | C11: 6115.6 | D11: 6115.6 | F11: 32 | G11: 32 | H11: 191.1125 | I11: 585.55 | J11: Вс
A12: 46249 | C12: 6446 | D12: 6446 | F12: 31 | G12: 31 | H12: 207.93548 | I12: 0 | J12: Сб
A13: 46248 | B13: 591 | C13: 11827.8 | D13: 12418.8 | E13: 1 | F13: 59 | G13: 60 | H13: 206.98 | I13: 480.37 | J13: Пт
A14: 46247 | B14: 251 | C14: 13319.4 | D14: 13570.4 | E14: 1 | F14: 72 | G14: 73 | H14: 185.89589 | I14: 0 | J14: Чт
A15: 46246 | B15: 1217 | C15: 15267 | D15: 16484 | E15: 4 | F15: 73 | G15: 77 | H15: 214.07792 | I15: 90.15 | J15: Ср
A16: 46245 | C16: 12954.4 | D16: 12954.4 | F16: 68 | G16: 68 | H16: 190.50588 | I16: 1291.19 | J16: Вт
A17: 46244 | C17: 10540.8 | D17: 10540.8 | F17: 60 | G17: 60 | H17: 175.68 | I17: 2142.85 | J17: Пн
A18: 46243 | C18: 3302 | D18: 3302 | F18: 17 | G18: 17 | H18: 194.23529 | I18: 3288.62 | J18: Вс
A19: 46242 | C19: 3453 | D19: 3453 | F19: 18 | G19: 18 | H19: 191.83333 | I19: 409.96 | J19: Сб
A20: 46241 | C20: 12341.6 | D20: 12341.6 | F20: 62 | G20: 62 | H20: 199.05806 | I20: 516.05 | J20: Пт
A21: 46240 | C21: 13887 | D21: 13887 | F21: 60 | G21: 60 | H21: 231.45 | I21: 409.67 | J21: Чт
A22: 46239 | C22: 12203 | D22: 12203 | F22: 51 | G22: 51 | H22: 239.27451 | I22: 134.26 | J22: Ср
A23: 46238 | C23: 13248 | D23: 13248 | F23: 54 | G23: 54 | H23: 245.33333 | I23: 201.44 | J23: Вт
A24: 46237 | C24: 12406 | D24: 12406 | F24: 57 | G24: 57 | H24: 217.64912 | I24: 0 | J24: Пн
A25: 46236 | C25: 1715.2 | D25: 1715.2 | F25: 9 | G25: 9 | H25: 190.57778 | I25: 837.55 | J25: Вс
A26: 46235 | C26: 5137.4 | D26: 5137.4 | F26: 23 | G26: 23 | H26: 223.36522 | I26: 431.35 | J26: Сб
A27: 46234 | C27: 0 | F27: 0 | I27: 627.55 | J27: Пт
A28: 46233 | C28: 11428 | D28: 11428 | F28: 54 | G28: 54 | H28: 211.62963 | I28: 276.22 | J28: Чт
A29: 46232 | C29: 10835.8 | D29: 10835.8 | F29: 53 | G29: 53 | H29: 204.44906 | I29: 831.59 | J29: Ср
A30: 46231 | C30: 12639 | D30: 12639 | F30: 63 | G30: 63 | H30: 200.61905 | I30: 833.51 | J30: Вт
