Workbook
Name MY_FUNCTION1: LAMBDA(#REF!/#REF!*100%)

Sheet Оборудование Очаково
C1: Кол-во | F1: ИТОГ | G1: =SUM(G3:G202) -> 1195960
A2: № | B2: Наименование | C2: Надо | D2: Есть | E2: Купить | F2: Цена | G2: Стоимость | H2: Ссылка
A3: 1 | B3: Сковорода опрокидывающаяся | C3: 2 | D3: 1 | E3: =C3-D3 -> 1 | F3: 74000 | G3: =E3*F3 -> 74000 | H3: https://www.avito.ru/kirovskaya_oblast_kirov/oborudovanie_dlya_biznesa/skovoroda_oprokidyvayuschayasya_tula_sesm-03n_4167586681?context=H4sIAAAAAAAA_wE_AMD_YToyOntzOjEzOiJsb2NhbFByaW9yaXR5IjtiOjA7czoxOiJ4IjtzOjE2OiJzRUtOdmRzT0cyZnNXUWhPIjt9leFoFz8AAAA
A4: 2 | B4: Тестомес 60л Abbat | C4: 1 | D4: 1 | E4: =C4-D4 -> 0 | F4: 157000 | G4: =E4*F4 -> 0 | H4: https://abat.ru/catalog/testomesy/spiralnyy-testomes-tms-60nn-1r-serii-light/
A5: 3 | B5: Тестомесильная машина Miratek PX-40 | C5: 1 | D5: 0 | E5: =C5-D5 -> 1 | F5: 157000 | G5: =E5*F5 -> 157000
A6: 4 | B6: Мясорубка мим-600 | C6: 1 | D6: 0 | E6: =C6-D6 -> 1 | F6: 30000 | G6: =E6*F6 -> 30000 | H6: https://www.avito.ru/sankt-peterburg/bytovaya_tehnika/myasorubka_mim-600_7269946449?slocation=659020&context=H4sIAAAAAAAA_wE_AMD_YToyOntzOjEzOiJsb2NhbFByaW9yaXR5IjtiOjE7czoxOiJ4IjtzOjE2OiI4QlZRbWxyWHpSd2dDREF1Ijt9SgdCXT8AAAA
A7: 5 | B7: RobotCoupe CL50 E | C7: 1 | D7: 0 | E7: =C7-D7 -> 1 | F7: 75000 | G7: =E7*F7 -> 75000 | H7: https://www.avito.ru/samara/oborudovanie_dlya_biznesa/ovoscherezka_robot_coupe_cl50e_s_diskami_4605343063?segment=avitoForBusiness&slocation=659020&context=H4sIAAAAAAAA_wGDAHz_YTo0OntzOjk6ImZyb21TcGFjZSI7czoxNjoiYXZpdG9Gb3JCdXNpbmVzcyI7czoxMzoibG9jYWxQcmlvcml0eSI7YjoxO3M6Mzoic3JjIjtzOjEwOiJhZmJfc2VhcmNoIjtzOjE6IngiO3M6MTY6ImtjdlZxbkR6WkFQRzZoMmEiO31KVkvkgwAAAA
A8: 6 | B8: Индукционная конфорка | C8: 7 | D8: 4 | E8: =C8-D8 -> 3 | F8: 17000 | G8: =E8*F8 -> 51000 | H8: https://www.avito.ru/tyumen/oborudovanie_dlya_biznesa/plita_induktsionnaya_indokor_in3500_4613302168?context=H4sIAAAAAAAA_wE_AMD_YToyOntzOjEzOiJsb2NhbFByaW9yaXR5IjtiOjE7czoxOiJ4IjtzOjE2OiJPQ2JtbUtuWFpMUGdtZ3piIjt9gk7aRj8AAAA
A9: 7 | B9: Фильт для воды | C9: 1 | D9: 0 | E9: =C9-D9 -> 1 | F9: 40000 | G9: =E9*F9 -> 40000 | H9: https://vodni-standart.ru/?utm_source=yandex&utm_medium=cpc&utm_campaign=115908423&utm_term=---autotargeting&utm_banner=1859837756768689779&utm_phrase=53670918000&utm_content=premium/5&calltouch_tm=yd_c:115908423_gb:5512460668_ad:1859837756768689779_ph:53670918000_st:search_pt:premium_p:5_s:none_dt:desktop_reg:55_ret:53670918000_apt:none&yclid=9140691686113411071#rec837852192
A10: 8 | B10: Холодильник Polair 700 л | C10: 8 | D10: 6 | E10: =C10-D10 -> 2 | F10: 30000 | G10: =E10*F10 -> 60000 | H10: https://www.avito.ru/tyumen/oborudovanie_dlya_biznesa/holodilnyy_shkaf_polair_07_3875580478?context=H4sIAAAAAAAA_wE_AMD_YToyOntzOjEzOiJsb2NhbFByaW9yaXR5IjtiOjE7czoxOiJ4IjtzOjE2OiJOQnRNcWE2cWZpbVBTazd6Ijt9_C3HcD8AAAA
A11: 9 | B11: Стол нержавейка 1500х700мм | C11: 26 | D11: 8 | E11: =C11-D11 -> 18 | F11: 10100 | G11: =E11*F11 -> 181800 | H11: https://www.avito.ru/tyumen?cd=1&context=H4sIAAAAAAAA_0SRwXKbMBCG38XXHrLYdVycycERkSIiKRXjgOBmRIJxMEktgcCdvntHtWd6hF3tfP_379bB-rdZB7Ce6c_T6U3b5rOb3Zn17XdYz2hnNT3iQ0XaoWxd89K6Rh9TVxJ8KFLXMOyaQu39d5-r5KucLzU9fGlqUQXskOxDFAD7KYcmkkOFAvX06jh5dMAW0ghCgQ1ysOQBclcDu5FDOwY8ethzgRbAIjmEZANsldQViSh_PkH-lNQWfQNman_DVn5eSiPQBEzJvkK3wDY13746LggW541zJ9MrPPYQ38jB-nkkbYg8Q9JMUVILz_ie1CFaQX729x3kzM-kFf7fj9r9GjwDAraS_XTJAnkkrd9lTNoKLYGdpEGbUWw3jgqCaaQd588r1l48aTLu83lqi2wJCtFbheKmyMahCq4eSXreZVWfHtNJz__7Lo_hVGbYsAybQsX-rVEoNrtsedKB37ErheKpUDgolPh3-y1wjVZpq7v22od3zHz-FRUoBKZ87rl3YazP38neIkejx4BHUbLfasfxhask4eHabZxg17wc8uBlu5n4E3gOKNT-mofJznpHZ-8j9P3XlvArry1U8lnOkwtPJ0aNw0W5iD_yLm7zzLa6DT92WfVVYde8p0FI6_v72d2fvwEAAP__xFx2vaECAAA&q=стол+нержавейка+1500+х+700
A12: 10 | B12: Стол нержавейка 1200х700мм | C12: 11 | D12: 7 | E12: =C12-D12 -> 4 | F12: 9400 | G12: =E12*F12 -> 37600 | H12: https://www.avito.ru/tyumen?q=стол+нержавейка+1200+х+700
A13: 11 | B13: Стол нержавейка 600х600мм | C13: 2 | D13: 6 | E13: =C13-D13 -> -4 | F13: 5000 | G13: =E13*F13 -> -20000 | H13: У Олега их как грязи
A14: 12 | B14: Блинница автоматическая Sikom рк-1.2.20 | C14: 1 | D14: 1 | E14: =C14-D14 -> 0 | F14: 230000 | G14: =E14*F14 -> 0 | H14: https://www.avito.ru/ryazan/bytovaya_tehnika/blinnyy_apparat_sikom_7309630210
A15: 13 | B15: Ванна моечная 700х700 | C15: 6 | D15: 2 | E15: =C15-D15 -> 4 | F15: 9000 | G15: =E15*F15 -> 36000 | H15: https://www.avito.ru/tyumen/oborudovanie_dlya_biznesa/pishevoe/neitralnoe/moecnoe_oborudovanie-ASgBAgICA0TqAvpPkKUU5vaOA6ylFPj3jgM?q=ванна+моечная+70
A16: 14 | B16: Ванна моечная двойная 1150х700 | C16: 3 | D16: 3
A17: 15 | B17: Автоматический жироуловитель СПБ 1,0-70 Автосбор | C17: 4 | D17: 0 | E17: =C17-D17 -> 4 | F17: 49500 | G17: =E17*F17 -> 198000 | H17: https://polyfacture.ru/catalog/zhirouloviteli-avtosbor/23355/
A18: 16 | B18: Шкаф для одежды ШМ-24 | C18: 8 | D18: 4 | E18: =C18-D18 -> 4 | F18: 16390 | G18: =E18*F18 -> 65560 | H18: https://тюмень.железная-мебель.рф/catalog/metallicheskie-shkafy/shkafy-metallicheskie-dlya-razdevalok/shkafy-dlya-odezhdy/shkaf-dlya-odezhdy-shm-24/
A19: 17 | B19: Ванна моечная большая | C19: 5 | D19: 0 | E19: =C19-D19 -> 5 | G19: =E19*F19 -> 0
A20: 18 | B20: Слайсер | C20: 3 | D20: 1 | E20: =C20-D20 -> 2 | F20: 25000 | G20: =E20*F20 -> 50000
A21: 19 | B21: Тележка-шпилька 16уровней | C21: 8 | D21: 4 | E21: =C21-D21 -> 4 | G21: =E21*F21 -> 0
A22: 20 | B22: Весы напольные | C22: 6 | D22: 5 | E22: =C22-D22 -> 1 | F22: 5000 | G22: =E22*F22 -> 5000 | H22: https://www.avito.ru/tyumen/oborudovanie_dlya_biznesa/vesy_napolnye_elektronnye_torgovye_7509978347?segment=avitoForBusiness&utm_campaign=native&utm_medium=item_page_android&utm_source=soc_sharing
A23: 21 | B23: Рукомойник | C23: 8 | D23: 4 | E23: =C23-D23 -> 4 | G23: =E23*F23 -> 0
A24: 22 | B24: Зонт вытяжной, островной | C24: 1 | D24: 0 | E24: =C24-D24 -> 1 | F24: 70000 | G24: =E24*F24 -> 70000
A25: 23 | B25: Печь пекарская с растойкой 10 уровней | C25: 1 | D25: 1 | E25: =C25-D25 -> 0 | F25: 270000 | G25: =E25*F25 -> 0
A26: 24 | B26: Машина стиральная | C26: 1 | D26: 0 | E26: =C26-D26 -> 1 | F26: 25000 | G26: =E26*F26 -> 25000
A27: 25 | B27: Машина сушильная | C27: 1 | D27: 0 | E27: =C27-D27 -> 1 | F27: 20000 | G27: =E27*F27 -> 20000
A28: 26 | B28: Керхер | C28: 1 | D28: 0 | E28: =C28-D28 -> 1 | F28: 5000 | G28: =E28*F28 -> 5000
A29: 27 | B29: Планетарный миксер, дежа 10 литров | C29: 1 | D29: 0 | E29: =C29-D29 -> 1 | F29: 35000 | G29: =E29*F29 -> 35000 | H29: https://www.avito.ru/tyumen/oborudovanie_dlya_biznesa/mikser_planetarnyy_foodatlas_b-20ba_eco20l_4679194856?utm_campaign=native&utm_medium=item_page_android&utm_source=soc_sharing
A30: 28 | B30: Котел пищеварочный | C30: 1 | E30: =C30-D30 -> 1 | G30: =E30*F30 -> 0 | H30: https://www.avito.ru/ekaterinburg/oborudovanie_dlya_biznesa/kotel_varochnyy_abat_kpem-160-o_4254362678?utm_campaign=native&utm_medium=item_page_android&utm_source=soc_sharing
A31: 29 | B31: Погружной блендер | E31: =C31-D31 -> 0 | G31: =E31*F31 -> 0
E32: =C32-D32 -> 0 | G32: =E32*F32 -> 0
G33: =C33*F33 -> 0

Sheet Факт очаково
A1: Наименование | B1: Кол-во
A2: - [ ] Мойка двойная 135х70 | B2: 1
A3: - [ ] Мойка двух секционная 115х70 | B3: 3
A4: - [ ] Мойка 70х70 | B4: 2
A5: - [ ] Рукомойник 50х50 | B5: 3
A6: - [ ] Рукомойник 40х40 | B6: 1
A8: - [ ] Стол 150х70 деревянная столешница | B8: 2
A9: - [ ] Стол 150х70 | B9: 8
A10: - [ ] Стол 150х60 | B10: 1
A11: - [ ] Стол 120х70 | B11: 7
A12: - [ ] Стол 120х70 состояние плохое | B12: 1
A13: - [ ] Стол 120х60 | B13: 1
A14: - [ ] Стол 70х90 | B14: 2
... A54: - [ ] Блок раздачи с полкой 112х73 с внутренними шкафами | B54: 1

Sheet Бинятов ассортимент
A1: БИНЯТОВСКИЙ ХЛЕБОКОМБИНАТ
A3: Адрес: г.Тюмень, Судостроителей 42
A5: Колл-центр: +7(3452)48-10-24, +7(922)489-6207
A7: Менеджер: +7 902 551-15-51
A9: Прайс-лист Хлебобулочной продукции 25.10.2024г.
A11: Наименование товаров | B11: Срок хранения (часов) | C11: Цена за шт./руб. | D11: Кол-во, шт
A12: ХЛЕБ Пшеничный
A13: Хлеб Пшеничный из муки первого сорта 0,5кг неупак. | B13: 24 | C13: 33
A14: Хлеб Пшеничный из муки первого сорта 0,5кг нарезка упак. | B14: 72 | C14: 36
A15: Хлеб Пшеничный из муки первого сорта 0,250 кг неупак. | B15: 24 | C15: 22
A16: Хлеб Пшеничный из муки первого сорта 0,250 кг упак. | B16: 72 | C16: 26
A17: Хлеб Тартин 0,4кг упак. | B17: 72 | C17: 44
A18: Хлеб Тартин 0,4кг неупак. | B18: 24 | C18: 40
A19: Хлеб Тостовый из муки высшего сорта 0,4кг нарезка упак. | B19: 72 | C19: 40
A20: Мини багет 0,200 кг неупак, шт. | B20: 24 | C20: 27
A21: Чиабатта пшеничная 0,250 кг неупак. шт. | B21: 24 | C21: 32
A22: ХЛЕБ пшенично-ржаной
A23: Хлеб Дарницкий 0,6кг неупак | B23: 24 | C23: 39
A24: Хлеб Дарницкий 0,6кг нарезка упак. | B24: 72 | C24: 44
A25: Хлеб Дарницкий 0,28кг нарезка упак. | B25: 72 | C25: 29
A26: Хлеб Бородинский 0,4кг неупак. | B26: 24 | C26: 37
A27: Хлеб Бородинский 0,4кг нарезка упак. | B27: 72 | C27: 40
A28: Хлеб ржано-пшеничный «Николаевский» 0,5кг неупак | B28: 24 | C28: 40
A29: Хлеб ржано-пшеничный «Николаевский» 0,5кг нарезка упак | B29: 96 | C29: 47
A30: Хлеб ржано-пшеничный «Николаевский» 0,24кг нарезка упак | B30: 96 | C30: 29
A31: Хлеб «Тостовый ржаной» 0,3кг нарезка упак. | B31: 96 | C31: 32
A32: Хлеб «Украинский новый» 0,55кг неупак | B32: 24 | C32: 38
A33: Хлеб «Украинский новый» 0,55кг нарезка упак. | B33: 72 | C33: 45
A34: Хлеб «Гречневый» 0,2 кг. упак. шт. | B34: 72 | C34: 38
... A37: Хлеб пшенично-ржаной "Купеческий" 0,250 кг упак. | B37: 72 | C37: 38
A38: ХЛЕБ Диетический/обогащенный
A39: Хлеб Бурже 0,3кг упак | B39: 96 | C39: 74
A40: Хлеб с отрубями 0,3кг неупак. | B40: 24 | C40: 32
A41: Хлеб с отрубями 0,3кг нарезка упак. | B41: 72 | C41: 36
A42: Хлеб Кукурузный 0,3кг неупак. | B42: 24 | C42: 62
A43: Хлеб Кукурузный 0,3кг упак. | B43: 72 | C43: 68
A44: Хлеб "Трапезный" бездрожжевой 0,25 кг неупак., шт | B44: 24 | C44: 43
A45: Хлеб "Трапезный" бездрожжевой 0,25 кг упак., шт | B45: 72 | C45: 45
A46: Батон с отрубями 0,3кг нарезка упак. | B46: 96 | C46: 38
A47: БУЛОЧНЫЕ изделия
...

Sheet Расчет Реском
B2: Матрица блюд ПЕРВАЯ неделя
C3: код | D3: Завтрак | E3: Шт | F3: код | G3: Салат | H3: Шт | I3: код | J3: Суп | K3: Шт | L3: код | M3: Второе | N3: Шт | O3: код | P3: Выпечка | Q3: Шт | R3: код | S3: Сэндвич | T3: Шт | U3: код | V3: Япония | W3: Шт
A4: 46145 | B4: Вс. | C4: 385 | D4: Омлет воздушный | E4: 83 | F4: 3076 | G4: Салат ''Оливье'' (колбаса варен) | H4: 98 | I4: 793 | J4: Борщ с курицей | K4: 106 | L4: 4013 | M4: Свинина с тмином со сложным гарниром | N4: 187 | X4: Птица
C5: 4036 | D5: Каша рисовая с вишней | E5: 114 | F5: 4009 | G5: Салат ''Винегрет'' (без капусты) 120 г | H5: 98 | I5: 822 | J5: Хлеб пшеничный | K5: 5 | L5: 4014 | M5: Филе с сыром и макаронами | N5: 205 | X5: Свинина
X6: Рыба
X7: Покупное
X8: Говядина
C12: код | D12: Завтрак | E12: Шт | F12: код | G12: Салат | H12: Шт | I12: код | J12: Суп | K12: Шт | L12: код | M12: Второе | N12: Шт | O12: код | P12: Выпечка | Q12: Шт | R12: код | S12: Сэндвич | T12: Шт | U12: код | V12: Япония | W12: Шт
A13: 46146 | B13: пн | C13: 2730 | D13: Блины со сгущенкой | F13: 4024 | G13: Салат "Чешский" (колбаса п/к) | I13: 8 | J13: Суп гороховый 250 мл | L13: 48 | M13: Голубец с картофельным пюре | O13: 3435 | P13: Булочка с повидлом 80 г | R13: 654 | S13: Сэндвич с бужениной и соусом Релиш | U13: 2943 | V13: Онигири с куриным филе в соусе спайси
C14: 1550 | D14: Омлет с овощами и сыром | F14: 3379 | G14: Салат ''Зайка'' 120 г | L14: 4026 | M14: Минтай в сырной корочке с рисом радуга | O14: 3455 | P14: Слойка с ветчиной и сыром 100г | R14: 2083 | S14: Сэндвич ''Цезарь''
F15: 3244 | G15: Салат ''Крабик'' с рисом | I15: 822 | J15: Хлеб пшеничный | L15: 4030 | M15: Курочка с овощной сальсой и спагетти | U15: 4000 | V15: Компот из сухофруктов 0,5 л
F16: 3343 | G16: Боул с тунцом , бобами эдамаме и овощами | L16: 859 | M16: Бедро запеченное с макаронами | N16: только СПК
L17: 958 | M17: Поджарка из курицы с рисом
L18: 4029 | M18: Жаркое по-домашнему со свининой | N18: только СПК
L19: 238 | M19: Жаркое по-домашнему 400 грамм | N19: СПК
C21: код | D21: Завтрак | E21: Шт | F21: код | G21: Салат | H21: Шт | I21: код | J21: Суп | K21: Шт | L21: код | M21: Второе | N21: Шт | O21: код | P21: Выпечка | Q21: Шт | R21: код | S21: Сэндвич | T21: Шт | U21: код | V21: Япония | W21: Шт
A22: 46147 | B22: Вт. | C22: 4035 | D22: Драники с сырной начинкой | F22: 3233 | G22: Салат ''Винегрет'' (без капусты) 120 г | I22: 386 | J22: Суп ''Харчо'' с курицей | L22: 761 | M22: Бризоль с рисом и овощами | O22: 3375 | P22: Самса с куриной грудкой 150 грамм | R22: 3486 | S22: Сэндвич с курицей и соусом карри | U22: 3722 | V22: Онигири с куриным филе в соусе том ям
C23: 4036 | D23: Каша рисовая с вишней | F23: 3301 | G23: Салат ''Блинный'' (ветчина куриная) | I23: 822 | J23: Хлеб пшеничный | L23: 4172 | M23: Свинина в соусе тонкацу со спагетти | R23: 2782 | S23: Сэндвич с пепперони и сыром
C24: 3045 | D24: Сырники с вишневой начинкой | F24: 4038 | G24: Салат "Гавайский" (курица, ананас) | L24: 4031 | M24: Мясо по-французски (свинина) | N24: спк | U24: 3997 | V24: Морс облепиховый 0,5 л
L25: 3437 | M25: Макароны по-флотски | N25: СПК
F26: 4034 | G26: Гранатовый браслет 220гр | L26: 763 | M26: Котлета куриная с картофельным пюре | N26: только СПК
L28: 3827 | M28: Курица Пармиджано с фарфале
L29: 3883 | M29: Аджапсандал
C30: код | D30: Завтрак | E30: Шт | F30: код | G30: Салат | H30: Шт | I30: код | J30: Суп | K30: Шт | L30: код | M30: Второе | N30: Шт | O30: код | P30: Выпечка | Q30: Шт | R30: код | S30: Сэндвич | T30: Шт | U30: код | V30: Япония | W30: Шт
A31: 46148 | B31: Ср. | C31: 4045 | D31: Панкейки шоколадные с вареньем | F31: 4048 | G31: Салат "Капустный" в маринаде | I31: 380 | J31: Солянка | L31: 4120 | M31: Курочка в сливочном соусе со спагетти | N31: СПК | O31: 3527 | P31: Хачапури 100 гр | R31: 3330 | S31: Сэндвич с курицей и соусом Барбекю | U31: 3723 | V31: Онигири с лососем и крем чиз
C32: 4056 | D32: Блинчики с курицей и грибами | F32: 4053 | G32: Салат "Арлекино" (колбаса вар.) | I32: 3752 | J32: Солянка мясная Комбо | L32: 1873 | M32: Колбаса ''Баварская'' с пюре и тушеной капустой | O32: 3454 | P32: Рулетик с корицей 100 гр | R32: 4051 | S32: Сэндвич с бужениной и горчичным соусом
F33: 4055 | G33: Салат "Чикаго" (кура копченая) | I33: 822 | J33: Хлеб пшеничный | L33: 1151 | M33: Тефтели куриные с гречкой | N33: СПК | O33: 2079 | P33: Вафельная трубочка с вареной сгущенкой | Q33: 200 | U33: 1474 | V33: Морс ягодный 0,5 л
F34: 3339 | G34: Боул ''Курица в имбирном соусе с овощами'' | L34: 1073 | M34: Горбуша запеченная с картофельным пюре
L35: 3663 | M35: Горбуша запеченная с рисом светофор | N35: только СПК
L37: 4032 | M37: Печень по-царски со сливочным пюре
C39: код | D39: Завтрак | E39: Шт | F39: код | G39: Салат | H39: Шт | I39: код | J39: Суп | K39: Шт | L39: код | M39: Второе | N39: Шт | O39: код | P39: Выпечка | Q39: Шт | R39: код | S39: Сэндвич | T39: Шт | U39: код | V39: Япония | W39: Шт
A40: 46149 | B40: Чт. | C40: 2951 | D40: Каша овсяная с яблоком и корицей | F40: 3323 | G40: Салат ''Морковь с чесноком'' 120гр | I40: 2288 | J40: Суп картофельный с курицей | O40: 3528 | P40: Сырная палочка | R40: 3223 | S40: Сэндвич с индейкой су-вид и овощами | U40: 3996 | V40: Морс вишневый 0,5 л
C41: 4037 | D41: Шарлотка с яблоком | F41: 4058 | G41: Салат "Городской"(колбаса вареная) | I41: 822 | J41: Хлеб пшеничный | L41: 4069 | M41: Бефстроганов (говядина) с картофелем | N41: пюре | R41: 5 | S41: Сэндвич с ветчиной и сыром | U41: 3021 | V41: Морс из ч/смородины 0,5 л
C42: 4070 | D42: Скрембл с сосиской и соусом | F42: 2706 | G42: Салат ''Фасолька'' с курицей | L42: 4067 | M42: Бефстроганов (говядина) с рисом | N42: рис
F43: 3823 | G43: Салат "Мимоза" с рыбой 220гр | L43: 4068 | M43: Бефстроганов (говядина) с макаронами | N43: макарон
L44: 547 | M44: Куриные шашлычки с картофелем запеченным
L45: 26 | M45: Плов по-узбекски с цыпленком б/250гр
L47: 3328 | M47: Спагетти с соусом ''Болоньезе'' 400 г
N48: ,
B49: Матрица блюд ВТОРАЯ неделя
...

Sheet Ёмкость точек
E1: Точки и ёмкость по категориям
A2: Ёмкость = макс. количество порций/единиц в холодильнике точки по категории. 0 = категория не везётся.
A3: № ТОЧКИ | B3: НАИМЕНОВАНИЕ ТОЧКИ | C3: Супы | D3: Салаты | E3: Вторые блюда | F3: Сэндвичи | G3: Завтраки | H3: Япония | I3: Напитки | J3: Десерты | K3: АКТИВНА
A4: 01 | B4: ЛеманаПРО Тобольский | C4: 3 | D4: 25 | E4: 32 | F4: 17 | G4: 17 | H4: 9 | I4: 12 | J4: 9 | K4: Да
A5: 02 | B5: Очаково | C5: 1 | D5: 7 | E5: 10 | F5: 4 | G5: 5 | H5: 3 | I5: 2 | J5: 2 | K5: Да
A6: 03 | B6: ЗапСибГазпром | C6: 1 | D6: 4 | E6: 8 | F6: 6 | G6: 5 | H6: 1 | I6: 2 | J6: 1 | K6: Да
A7: 04 | B7: Технологии ОФС | C7: 2 | D7: 7 | E7: 24 | F7: 8 | G7: 12 | H7: 2 | I7: 11 | J7: 4 | K7: Да
A8: 05 | B8: Бентек | C8: 2 | D8: 20 | E8: 29 | F8: 11 | G8: 15 | H8: 2 | I8: 13 | J8: 5 | K8: Да
A9: 06 | B9: ОФС Тобольский тр-т | C9: 1 | D9: 12 | E9: 18 | F9: 8 | G9: 4 | H9: 1 | I9: 7 | J9: 1 | K9: Да
A10: 07 | B10: Металл Профиль | C10: 1 | D10: 8 | E10: 9 | F10: 6 | G10: 5 | H10: 0 | I10: 6 | J10: 2 | K10: Да
A11: 08 | B11: ТубДиспансер | C11: 2 | D11: 13 | E11: 15 | F11: 7 | G11: 10 | H11: 2 | I11: 6 | J11: 3 | K11: Да
A12: 09 | B12: АИРТО | C12: 1 | D12: 15 | E12: 18 | F12: 8 | G12: 13 | H12: 3 | I12: 6 | J12: 4 | K12: Да
A13: 10 | B13: Скорая Суходольская | C13: 1 | D13: 11 | E13: 16 | F13: 9 | G13: 11 | H13: 3 | I13: 15 | J13: 6 | K13: Да
A14: 11 | B14: КАТРЕН | C14: 0 | D14: 6 | E14: 17 | F14: 5 | G14: 7 | H14: 0 | I14: 5 | J14: 5 | K14: Да
A15: 12 | B15: СПК АБК малое | C15: 1 | D15: 9 | E15: 11 | F15: 8 | G15: 10 | H15: 3 | I15: 5 | J15: 6 | K15: Да
... A32: 29 | B32: Поликлиника 17 (Монтажников) | C32: 1 | D32: 25 | E32: 29 | F32: 23 | G32: 20 | H32: 10 | I32: 18 | J32: 5 | K32: Да

Sheet карта готовности
A1: Общая рабочая таблица для пароконвектомата
A3: Температура по щупу — точка немедленной выгрузки.
A5: Тип сырья / изделия | B5: Температура камеры | C5: Влажность | D5: Температура готовности по щупу
A6: Курица, филе бедра | B6: 150 °C | C6: 0.6 | D6: 74 °C
A7: Курица, филе грудки | B7: 140 °C | C7: 0.8 | D7: 74 °C
A8: Свинина, порционные куски без кости | B8: 145 °C | C8: 0.6 | D8: 70 °C
A9: Говядина, порционные куски без кости | B9: 140 °C | C9: 0.7 | D9: 70 °C
A10: Баранина, порционные куски без кости | B10: 140 °C | C10: 0.7 | D10: 70 °C
A11: Рыба, филе или порционные куски | B11: 130 °C | C11: 0.8 | D11: 63 °C
A12: Фарш из говядины, свинины, смешанный фарш | B12: 140 °C | C12: 0.8 | D12: 72 °C
A13: Фарш из курицы или индейки | B13: 140 °C | C13: 0.8 | D13: 74 °C
A14: Котлеты из говядины, свинины, смешанного фарша | B14: 150 °C | C14: 0.6 | D14: 72 °C
A15: Котлеты из курицы или индейки | B15: 150 °C | C15: 0.6 | D15: 74 °C
A16: Котлеты рыбные | B16: 140 °C | C16: 0.7 | D16: 70 °C
A17: Запеканка с сырым мясом, птицей, рыбой или фаршем | B17: 140 °C | C17: 0.8 | D17: 74 °C
A18: Запеканка творожная или яичная | B18: 140 °C | C18: 0.7 | D18: 72 °C
A20: Температуру щупа не снижать при корректировке режима.
A22: Правила применения
A23: Камера должна быть предварительно разогрета.
A24: Сырьё — охлаждённое, полностью размороженное.
A25: Куски размещать в один слой без наложения.
A26: Щуп вводить в геометрический центр самого толстого изделия.
A27: Для запеканки щуп ставить в центр формы, в наиболее толстую часть.
A28: При достижении температуры по щупу продукт немедленно выгрузить.
A29: Если в смешанном составе присутствует сырая курица или индейка, устанавливать 74 °C.

Sheet Справочник + атрибуты
A1: По названию
A2: код | B2: Цена | C2: Название блюда | E2: Категория | F2: Атрибут 1 | G2: Атрибут 2 | H2: Атрибут 3 | I2: Эксперимент | J2: Комментарий | K2: Статус атрибутов | L2: Дата добавления | M2: Источник добавления | N2: Дата последней проверки
A3: 4013 | B3: 258 | C3: Фаршированная куриная ножка с макаронами | E3: Вторые блюда | F3: макароны | G3: курица | H3: кусок
A4: 4014 | B4: 210 | C4: Филе с сыром и печеным картофелем | E4: Вторые блюда | F4: картофель | G4: курица | H4: кусок
A5: 4015 | B5: 187 | C5: Свинина с тмином со сложным гарниром | E5: Вторые блюда | F5: овощи | G5: свинина | H5: соусное
A6: 4016 | B6: 148 | C6: Плов с грибами | E6: Вторые блюда | F6: моно-блюдо | G6: без мяса
A7: 1333 | B7: 188 | C7: Горбуша под овощной шапкой с рисом | E7: Вторые блюда | F7: рис | G7: рыба | H7: кусок
A8: 4196 | B8: 205 | C8: Филе с сыром и макаронами | E8: Вторые блюда | F8: макароны | G8: курица | H8: кусок
A9: 2931 | B9: 273 | C9: Паста Карбонара с беконом | E9: Вторые блюда | F9: макароны | G9: свинина | H9: соусное
A10: 763 | B10: 198 | C10: Котлета куриная с картофельным пюре | E10: Вторые блюда | F10: картофель | G10: курица | H10: фарш
A11: 48 | B11: 198 | C11: Голубец с картофельным пюре | E11: Вторые блюда | F11: картофель | G11: свинина | H11: фарш
A12: 4026 | B12: 232 | C12: Минтай в сырной корочке с рисом радуга | E12: Вторые блюда | F12: рис | G12: рыба | H12: кусок
A13: 4030 | B13: 198 | C13: Курочка с овощной сальсой и спагетти | E13: Вторые блюда | F13: макароны | G13: курица | H13: соусное
A14: 859 | B14: 198 | C14: Бедро запеченное с макаронами | E14: Вторые блюда | F14: макароны | G14: курица | H14: кусок
A15: 958 | B15: 180 | C15: Поджарка из курицы с рисом | E15: Вторые блюда | F15: рис | G15: курица | H15: соусное
A16: 4029 | B16: 198 | C16: Жаркое по-домашнему со свининой | E16: Вторые блюда | F16: моно-блюдо | G16: свинина
A17: 238 | B17: 198 | C17: Жаркое по-домашнему 400 грамм | E17: Вторые блюда | F17: моно-блюдо | G17: свинина
A18: 761 | B18: 180 | C18: Бризоль с рисом и овощами | E18: Вторые блюда | F18: рис | G18: курица | H18: кусок
A19: 4172 | B19: 203 | C19: Свинина в соусе тонкацу со спагетти | E19: Вторые блюда | F19: макароны | G19: свинина | H19: соусное
A20: 18 | B20: 198 | C20: Мясо по-французски | E20: Вторые блюда | F20: картофель | G20: курица
A21: 4031 | B21: 211 | C21: Мясо по-французски (свинина) | E21: Вторые блюда | F21: картофель | G21: свинина
A22: 3437 | B22: 188 | C22: Макароны по-флотски | E22: Вторые блюда | F22: макароны | G22: курица
A23: 102 | B23: 264 | C23: Соба с курицей в устричном соусе | E23: Вторые блюда | F23: макароны | G23: курица | H23: соусное
A24: 3517 | B24: 215 | C24: Тилапия в соусе сальса с рисом | E24: Вторые блюда | F24: рис | G24: рыба | H24: кусок
A25: 1873 | B25: 188 | C25: Колбаса ''Баварская'' с пюре и тушеной капустой | E25: Вторые блюда | F25: овощи | G25: свинина | H25: кусок
A26: 1151 | B26: 198 | C26: Тефтели куриные с гречкой | E26: Вторые блюда | F26: крупа | G26: курица | H26: фарш
A27: 1073 | B27: 188 | C27: Горбуша запеченная с картофельным пюре | E27: Вторые блюда | F27: картофель | G27: рыба | H27: кусок
A28: 3239 | B28: 215 | C28: Минтай под овощами с рисом Радуга | E28: Вторые блюда | F28: рис | G28: рыба | H28: кусок
A29: 4032 | B29: 210 | C29: Печень по-царски со сливочным пюре | E29: Вторые блюда | F29: картофель | G29: говядина | H29: соусное
A30: 1327 | B30: 188 | C30: Манты по-дагестански | E30: Вторые блюда | F30: без гарнира | G30: свинина
A31: 4069 | B31: 265 | C31: Бефстроганов (говядина) с картофелем | E31: Вторые блюда | F31: картофель | G31: говядина | H31: соусное
A32: 4067 | B32: 265 | C32: Бефстроганов (говядина) с рисом | E32: Вторые блюда | F32: рис | G32: говядина | H32: соусное
A33: 4068 | B33: 265 | C33: Бефстроганов (говядина) с макаронами | E33: Вторые блюда | F33: макароны | G33: говядина | H33: соусное
A34: 547 | B34: 215 | C34: Куриные шашлычки с картофелем запеченным | E34: Вторые блюда | F34: картофель | G34: курица | H34: кусок
A35: 26 | B35: 165 | C35: Плов по-узбекски с цыпленком б/250гр | E35: Вторые блюда | F35: моно-блюдо | G35: курица
A36: 2687 | B36: 188 | C36: Котлета куриная с картофелем | E36: Вторые блюда | F36: картофель | G36: курица | H36: фарш
A37: 113 | B37: 198 | C37: Спагетти ''Болоньезе'' | E37: Вторые блюда | F37: моно-блюдо | G37: свинина
A38: 3737 | B38: 208 | C38: Чкмерули из курицы со спагетти | E38: Вторые блюда | F38: макароны | G38: курица | H38: соусное
A39: 1009 | B39: 160 | C39: Свинина по-баварски с картофелем | E39: Вторые блюда | F39: картофель | G39: курица | H39: соусное
A40: 980 | B40: 188 | C40: Филе с грибами и картофельным пюре | E40: Вторые блюда | F40: картофель | G40: курица | H40: кусок
...

Sheet Справочник атрибутов
A1: Категория | B1: Атрибут 1 | C1: Атрибут 2 | D1: Атрибут 3 | E1: Эксперимент | F1: Комментарий
A2: Десерты | B2: выпечка | C2: лёгкий
B3: кремовый | C3: сытный
B4: творожный
B5: фруктовый
B6: шоколадный
A8: Категория | B8: Атрибут 1 | C8: Атрибут 2 | D8: Атрибут 3 | E8: Эксперимент | F8: Комментарий
A9: Завтраки | B9: каша | C9: лёгкий
B10: блины сладкие | C10: сытный
B11: блины сытные
B12: сырники
B13: вафли
B14: выпечка
B15: яичное блюдо
A17: Категория | B17: Атрибут 1 | C17: Атрибут 2 | D17: Атрибут 3 | E17: Эксперимент | F17: Комментарий
A18: Салаты | B18: овощной | C18: овощи
B19: слоёный | C19: курица
B20: майонезный | C20: мясо
B21: премиальный | C21: рыба
B22: боул | C22: без белка
B23: масляный | C23: морепрод.
B24: азиатский
A26: Категория | B26: Атрибут 1 | C26: Атрибут 2 | D26: Атрибут 3 | E26: Эксперимент | F26: Комментарий
A27: Супы | B27: бульон | C27: курица
B28: крем-суп | C28: мясо
B29: густой | C29: рыба
B30: лёгкий | C30: без мяса
A32: Категория | B32: Атрибут 1 | C32: Атрибут 2 | D32: Атрибут 3 | E32: Эксперимент | F32: Комментарий
A33: Вторые блюда | B33: картофель | C33: курица | D33: кусок
B34: макароны | C34: свинина | D34: фарш
B35: рис | C35: говядина | D35: соусное
B36: крупа | C36: рыба
B37: овощи | C37: без мяса
B38: без гарнира
B39: моно-блюдо
A41: Категория | B41: Атрибут 1 | C41: Атрибут 2 | D41: Атрибут 3 | E41: Эксперимент | F41: Комментарий
A42: Сэндвичи | B42: куриный | C42: лёгкий
B43: мясной | C43: сытный
B44: рыбный
B45: овощной
...

Sheet Меню НА СЛЕДУЮЩИЙ МЕСЯЦ
B1: ЭТОТ ЛИСТ ДЛЯ ОЛИ ТЕХНОЛОГА БОЛЬШЕ НИКТО СЮДА НЕ ЛЕЗЕТ!!!
B2: Матрица блюд ПЕРВАЯ неделя
B3: день | C3: Завтрак | D3: Цена | E3: Салат | F3: Цена | G3: Суп | I3: Второе | K3: десерты | L3: Цена | M3: гарнир | N3: Цена | O3: Сэндвич | P3: Цена | R3: .
A4: 46024 | G4: Тыквенный крем-суп с имбирём | I4: Котлета домашняя с пюре | Q4: Птица
A5: ост | I5: Отбивная из курицы с Фарфале | Q5: Свинина
I6: Сердечки | Q6: Рыба
I7: Манты
I9: Говядина в имбирном соусе | Q9: Покупное
Q11: Говядина
A12: 46027 | Q12: япошка
A13: шад
A19: 46030
A20: ост.шад
Q42: Птица
A43: 45753 | Q43: Свинина
Q44: Рыба
Q48: овощное
Q49: Говядина
Q82: Птица
A83: 45761 | Q83: Свинина
Q84: Рыба
Q85: Покупное
Q86: Говядина
Q110: Птица
A111: 20.04 | Q111: Свинина
Q112: Рыба
Q113: Покупное
Q114: Говядина
A115: 45768
A120: 45769
A125: 45770
A130: 45771
C140: Вот ингредиенты на 4 персоны: 1 литр томатного соуса; 50 г сливочного масла; 50 г муки; 500 мл молока; половинка луковицы; несколько листьев базилика; соль, черный перец, тертый мускатный орех и масло по вкусу. В кастрюле с высокими бортами приготовьте томатный соус. Налейте масло и добавьте нарезанную половину лука. Когда он станет золотистым, добавьте помидор, соль и дайте ему приготовиться, добавьте свежие листьями базилика. Тем временем приготовьте соус бешамель в небольшой кастрюле: дайте маслу растаять и медленно добавьте просеянную муку, хорошо перемешивая — обратите на этот шаг пристальное внимание, потому что могут легко образовываться комочки. Когда мука станет золотистой, понемногу вливайте молоко и перемешивайте венчиком; уменьшите огонь и часто помешивайте, пока молоко не загустеет и не образуется бархатистый крем. На этом этапе добавьте соль, перец и много тертого мускатного ореха, чтобы придать бешамелю характерный вкус. Вы можете смешать соус бешамель с томатным, чтобы консистенция получилась более однородной, или вылить оба соуса на пасту отдельно.

Sheet новогодние прзд.
G1: 12 | I1: 11 | K1: 53 | M1: 35 | O1: 85 | Q1: ? | S1: 16 | U1: 19 | W1: 13 | Y1: 14 | AA1: 17 | AC1: 19 | AE1: 27 | AG1: 14 | AI1: 11
A2: Дата: | C2: 45659 | D2: План на день кухня ПЯТНИЦА | N2: - РАБОТАЕТ | T2: - ВЫХОДНОЙ
A3: № | B3: Код | C3: Вид | D3: Название блюда | E3: Т 1 | F3: Ф 1 | G3: Т2 | H3: Ф2 | I3: Т 3 | J3: Ф 3 | K3: Т 4 | L3: Ф 4 | M3: Т 5 | N3: Ф 5 | O3: Т 6 | P3: Ф 6 | Q3: Т 7 | R3: Ф7 | S3: Т8 | T3: Ф8 | U3: Т9 | V3: Ф9 | W3: Т10 | X3: Ф10 | Y3: Т11 | Z3: Ф11 | AA3: Т12 | AB3: Ф12 | AC3: Т13 | AD3: Ф13 | AE3: Т14 | AF3: Ф14 | AG3: Т15 | AH3: Ф15 | AI3: Т16 | AJ3: Ф16 | AK3: Т17 | AL3: Ф17 | AM3: Т18 | AN3: Ф18 | AO3: Т19 | AP3: Ф19 | AQ3: Т20 | AR3: Ф20 | AS3: Т21 | AT3: Ф21 | AU3: Т22 | AV3: Ф22 | AW3: БПЮ | AX3: ФБПЮ | AY3: ПЛАН | AZ3: ФАКТ | BA3: ВМ | BB3: СПК | BC3: Выход | BD3: Масса
D4: Кол-во человек | E4: ОБЫЧ РЕЖ | K4: 40 | S4: ПО ВЫХ ДН | W4: ОБЫЧ РЕЖ | AE4: 15-20 | AK4: 30-50 | AQ4: ОБЫЧ РЕЖ | AS4: 20 | AU4: ОБЫЧ РЕЖ | AW4: 45780
D5: Когда выходят работать | AS5: С 04.01
A6: 1 | B6: 2423 | C6: ='Матрица 4 недели'!D3 -> Завтрак | D6: ='Меню НА СЛЕДУЮЩИЙ МЕСЯЦ'!C4 | E6: 20 | F6: 20 | K6: 10 | L6: 10 | O6: 9 | P6: 9 | S6: 5 | T6: 5 | W6: 10 | X6: 10 | Y6: 5 | Z6: 5 | AE6: 5 | AF6: 5 | AK6: 5 | AL6: 5 | AQ6: 10 | AR6: 10 | AU6: 8 | AV6: 8 | AY6: =(E6+G6+I6+K6+M6+O6+Q6+S6+U6+W6+Y6+AA6+AC6+AE6+AG6+AI6+AK6+AM6+AW6+AO6+AQ6+AS6+AU6)+1 -> 88 | AZ6: =F6+H6+J6+L6+N6+P6+R6+T6+V6+X6+Z6+AD6+AB6+AF6+AH6+AJ6+AL6+AR6+AX6+AN6+AP6+AT6+AV6 -> 87 | BA6: =111*AZ6 -> 9657 | BC6: 0.15 | BD6: =AY6*BC6 -> 13.2
A7: 2 | B7: 3624 | C7: ='Матрица 4 недели'!D145 -> Завтрак | D7: ='Меню НА СЛЕДУЮЩИЙ МЕСЯЦ'!C5 | E7: 20 | F7: 20 | K7: 10 | L7: 10 | O7: 9 | P7: 9 | S7: 5 | T7: 5 | W7: 10 | X7: 10 | Y7: 5 | Z7: 5 | AE7: 5 | AF7: 5 | AK7: 5 | AL7: 5 | AQ7: 10 | AR7: 10 | AU7: 8 | AV7: 8 | AY7: =(E7+G7+I7+K7+M7+O7+Q7+S7+U7+W7+Y7+AA7+AC7+AE7+AG7+AI7+AK7+AM7+AW7+AO7+AQ7+AS7+AU7)+1 -> 88 | AZ7: =F7+H7+J7+L7+N7+P7+R7+T7+V7+X7+Z7+AD7+AB7+AF7+AH7+AJ7+AL7+AR7+AX7+AN7+AP7+AT7+AV7 -> 87 | BA7: =97*AZ7 -> 8439
A8: 3 | B8: 3170 | C8: салат | D8: ='Меню НА СЛЕДУЮЩИЙ МЕСЯЦ'!E6 | E8: 30 | F8: 30 | L8: 5 | X8: 5 | AQ8: 20 | AR8: 20 | AY8: =(E8+G8+I8+K8+M8+O8+Q8+S8+U8+W8+Y8+AA8+AC8+AE8+AG8+AI8+AK8+AM8+AW8+AO8+AQ8+AS8+AU8)+1 -> 51 | AZ8: =F8+H8+J8+L8+N8+P8+R8+T8+V8+X8+Z8+AD8+AB8+AF8+AH8+AJ8+AL8+AR8+AX8+AN8+AP8+AT8+AV8 -> 60 | BA8: =85*AZ8 -> 5100
A9: 4 | B9: 47 | C9: ='Матрица 4 недели'!G3 -> Салат | D9: ='Меню НА СЛЕДУЮЩИЙ МЕСЯЦ'!E4 | E9: 30 | F9: 30 | K9: 15 | L9: 10 | O9: 15 | P9: 15 | S9: 5 | T9: 5 | W9: 18 | X9: 13 | Y9: 5 | Z9: 5 | AE9: 10 | AF9: 10 | AK9: 8 | AL9: 7 | AQ9: 20 | AR9: 20 | AU9: 20 | AV9: 20 | AY9: =(E9+G9+I9+K9+M9+O9+Q9+S9+U9+W9+Y9+AA9+AC9+AE9+AG9+AI9+AK9+AM9+AW9+AO9+AQ9+AS9+AU9)+1 -> 147 | AZ9: =F9+H9+J9+L9+N9+P9+R9+T9+V9+X9+Z9+AD9+AB9+AF9+AH9+AJ9+AL9+AR9+AX9+AN9+AP9+AT9+AV9 -> 135 | BA9: =98*AZ9 -> 13230 | BB9: =60*AX9 -> 0 | BC9: 0.1 | BD9: =AY9*BC9 -> 14.7
A10: 5 | B10: 3651 | C10: ='Матрица 4 недели'!G3 -> Салат | D10: ='Меню НА СЛЕДУЮЩИЙ МЕСЯЦ'!E5 | E10: 30 | F10: 35 | K10: 15 | L10: 20 | O10: 15 | P10: 15 | S10: 5 | T10: 5 | W10: 18 | X10: 23 | Y10: 5 | Z10: 5 | AE10: 10 | AF10: 10 | AK10: 8 | AL10: 8 | AQ10: 20 | AR10: 25 | AU10: 20 | AV10: 23 | AY10: =(E10+G10+I10+K10+M10+O10+Q10+S10+U10+W10+Y10+AA10+AC10+AE10+AG10+AI10+AK10+AM10+AW10+AO10+AQ10+AS10+AU10)+1 -> 147 | AZ10: =F10+H10+J10+L10+N10+P10+R10+T10+V10+X10+Z10+AD10+AB10+AF10+AH10+AJ10+AL10+AR10+AX10+AN10+AP10+AT10+AV10 -> 169 | BA10: =98*(AZ10-AX10) -> 16562 | BB10: =60*AX10 -> 0 | BC10: 0.1 | BD10: =AY10*BC10 -> 14.7
A11: 6 | C11: ='Матрица 4 недели'!G3 -> Салат | AY11: =(E11+G11+I11+K11+M11+O11+Q11+S11+U11+W11+Y11+AA11+AC11+AE11+AG11+AI11+AK11+AM11+AW11+AO11+AQ11+AS11+AU11)+1 -> 1 | AZ11: =F11+H11+J11+L11+N11+P11+R11+T11+V11+X11+Z11+AD11+AB11+AF11+AH11+AJ11+AL11+AR11+AX11+AN11+AP11+AT11+AV11 -> 0 | BA11: =98*(AZ11-AX11) -> 0 | BB11: =60*AX11 -> 0 | BC11: 0.1 | BD11: =AY11*BC11 -> 0.1
A12: 10 | B12: 380 | C12: ='Матрица 4 недели'!J145 -> Суп | D12: ='Меню НА СЛЕДУЮЩИЙ МЕСЯЦ'!G4 -> Тыквенный крем-суп с имбирём | E12: 2 | F12: 2 | K12: 2 | L12: 2 | O12: 2 | P12: 2 | S12: 2 | T12: 2 | W12: 2 | X12: 2 | Y12: 2 | Z12: 2 | AE12: 2 | AF12: 2 | AK12: 2 | AL12: 2 | AQ12: 2 | AR12: 2 | AU12: 2 | AV12: 2 | AY12: =(E12+G12+I12+K12+M12+O12+Q12+S12+U12+W12+Y12+AA12+AC12+AE12+AG12+AI12+AK12+AM12+AW12+AO12+AQ12+AS12+AU12)+1 -> 21 | AZ12: =F12+H12+J12+L12+N12+P12+R12+T12+V12+X12+Z12+AD12+AB12+AF12+AH12+AJ12+AL12+AR12+AX12+AN12+AP12+AT12+AV12 -> 20 | BB12: =AZ12*60 -> 1200
A13: 12 | B13: 69 | C13: ='Матрица 4 недели'!M3 -> Второе | D13: ='Меню НА СЛЕДУЮЩИЙ МЕСЯЦ'!I4 -> Котлета домашняя с пюре | E13: 25 | F13: 20 | K13: 15 | L13: 13 | O13: 12 | P13: 12 | S13: 4 | T13: 4 | W13: 23 | X13: 20 | Y13: 4 | Z13: 4 | AE13: 8 | AF13: 8 | AK13: 4 | AL13: 4 | AQ13: 30 | AR13: 30 | AU13: 15 | AV13: 15 | AY13: =(E13+G13+I13+K13+M13+O13+Q13+S13+U13+W13+Y13+AA13+AC13+AE13+AG13+AI13+AK13+AM13+AW13+AO13+AQ13+AS13+AU13)+1 -> 141 | AZ13: =F13+H13+J13+L13+N13+P13+R13+T13+V13+X13+Z13+AD13+AB13+AF13+AH13+AJ13+AL13+AR13+AX13+AN13+AP13+AT13+AV13 -> 130 | BA13: =198*(AZ13-AX13) -> 25740 | BB13: =160*AX13 -> 0 | BC13: 0.3 | BD13: =AY13*BC13 -> 42.3
A14: 13 | B14: 3732 | C14: ='Матрица 4 недели'!M3 -> Второе | D14: ='Меню НА СЛЕДУЮЩИЙ МЕСЯЦ'!I5 -> Отбивная из курицы с Фарфале | E14: 20 | F14: 20 | K14: 10 | L14: 10 | O14: 7 | P14: 7 | S14: 2 | T14: 2 | W14: 18 | X14: 18 | Y14: 2 | Z14: 2 | AE14: 4 | AF14: 4 | AK14: 2 | AL14: 2 | AQ14: 25 | AR14: 25 | AU14: 10 | AV14: 10 | AY14: =(E14+G14+I14+K14+M14+O14+Q14+S14+U14+W14+Y14+AA14+AC14+AE14+AG14+AI14+AK14+AM14+AW14+AO14+AQ14+AS14+AU14)+1 -> 101 | AZ14: =F14+H14+J14+L14+N14+P14+R14+T14+V14+X14+Z14+AD14+AB14+AF14+AH14+AJ14+AL14+AR14+AX14+AN14+AP14+AT14+AV14 -> 100 | BA14: =AZ14*198 -> 19800 | BC14: 0.3 | BD14: =AY14*BC14 -> 30.3
A15: 14 | B15: 3731 | C15: =#REF! -> #REF! | D15: Биточки куриные с гречкой | E15: 25 | F15: 25 | K15: 15 | L15: 15 | O15: 12 | P15: 12 | S15: 4 | T15: 4 | W15: 23 | X15: 23 | Y15: 4 | Z15: 4 | AE15: 8 | AF15: 8 | AK15: 4 | AL15: 4 | AQ15: 30 | AR15: 30 | AU15: 15 | AV15: 15 | AY15: =(E15+G15+I15+K15+M15+O15+Q15+S15+U15+W15+Y15+AA15+AC15+AE15+AG15+AI15+AK15+AM15+AW15+AO15+AQ15+AS15+AU15)+1 -> 141 | AZ15: =F15+H15+J15+L15+N15+P15+R15+T15+V15+X15+Z15+AD15+AB15+AF15+AH15+AJ15+AL15+AR15+AX15+AN15+AP15+AT15+AV15 -> 140 | BA15: =198*AZ15 -> 27720
A16: 15 | B16: 3672 | C16: ='Матрица 4 недели'!M3 -> Второе | D16: ='Меню НА СЛЕДУЮЩИЙ МЕСЯЦ'!I9 -> Говядина в имбирном соусе | E16: 25 | F16: 24 | K16: 15 | L16: 12 | O16: 12 | P16: 9 | S16: 4 | T16: 3 | W16: 23 | X16: 20 | Y16: 4 | Z16: 3 | AE16: 8 | AF16: 4 | AK16: 4 | AL16: 3 | AQ16: 30 | AR16: 30 | AU16: 15 | AV16: 11 | AY16: =(E16+G16+I16+K16+M16+O16+Q16+S16+U16+W16+Y16+AA16+AC16+AE16+AG16+AI16+AK16+AM16+AW16+AO16+AQ16+AS16+AU16)+1 -> 141 | AZ16: =F16+H16+J16+L16+N16+P16+R16+T16+V16+X16+Z16+AD16+AB16+AF16+AH16+AJ16+AL16+AR16+AX16+AN16+AP16+AT16+AV16 -> 119 | BA16: =198*(AZ16-AX16) -> 23562 | BB16: =160*AX16 -> 0 | BC16: 0.3 | BD16: =AY16*BC16 -> 42.3
A17: 16 | B17: 3537 | C17: сэндвич | D17: ='Меню НА СЛЕДУЮЩИЙ МЕСЯЦ'!O4 | E17: 20 | F17: 26 | K17: 20 | L17: 26 | O17: 5 | P17: 8 | S17: 3 | T17: 6 | W17: 10 | X17: 17 | Y17: 4 | Z17: 7 | AE17: 4 | AF17: 7 | AQ17: 15 | AR17: 22 | AU17: 4 | AV17: 6 | AY17: =(E17+G17+I17+K17+M17+O17+Q17+S17+U17+W17+Y17+AA17+AC17+AE17+AG17+AI17+AK17+AM17+AW17+AO17+AQ17+AS17+AU17)+1 -> 86 | AZ17: =F17+H17+J17+L17+N17+P17+R17+T17+V17+X17+Z17+AD17+AB17+AF17+AH17+AJ17+AL17+AR17+AX17+AN17+AP17+AT17+AV17 -> 125 | BA17: =188*(AZ17-AX17) -> 23500 | BB17: =160*AX17 -> 0
A18: 17 | B18: 3733 | D18: Чкмерули из курицы с гречкой | E18: 5 | F18: 5 | K18: 5 | L18: 5 | O18: 4 | P18: 4 | S18: 2 | T18: 2 | W18: 5 | X18: 5 | Y18: 2 | Z18: 3 | AE18: 4 | AF18: 4 | AK18: 2 | AL18: 2 | AQ18: 5 | AR18: 5 | AU18: 5 | AV18: 4 | AY18: =(E18+G18+I18+K18+M18+O18+Q18+S18+U18+W18+Y18+AA18+AC18+AE18+AG18+AI18+AK18+AM18+AW18+AO18+AQ18+AS18+AU18)+1 -> 40 | AZ18: =F18+H18+J18+L18+N18+P18+R18+T18+V18+X18+Z18+AD18+AB18+AF18+AH18+AJ18+AL18+AR18+AX18+AN18+AP18+AT18+AV18 -> 39 | BA18: =188*(AZ18-AX18) -> 7332
A19: 18 | AY19: =(E19+G19+I19+K19+M19+O19+Q19+S19+U19+W19+Y19+AA19+AC19+AE19+AG19+AI19+AK19+AM19+AW19+AO19+AQ19+AS19+AU19)+1 -> 1 | AZ19: =F19+H19+J19+L19+N19+P19+R19+T19+V19+X19+Z19+AD19+AB19+AF19+AH19+AJ19+AL19+AR19+AX19+AN19+AP19+AT19+AV19 -> 0 | BA19: =188*(AZ19-AX19) -> 0
A20: 19 | C20: Доп-но | AY20: =(E20+G20+I20+K20+M20+O20+Q20+S20+U20+W20+Y20+AA20+AC20+AE20+AG20+AI20+AK20+AM20+AW20+AO20+AQ20+AS20+AU20)+1 -> 1 | AZ20: =F20+H20+J20+L20+N20+P20+R20+T20+V20+X20+Z20+AD20+AB20+AF20+AH20+AJ20+AL20+AR20+AX20+AN20+AP20+AT20+AV20 -> 0 | BA20: =188*(AZ20-AX20) -> 0 | BC20: 0.3 | BD20: =AY20*BC20 -> 0.3
A21: 20 | B21: 3691 | C21: Доп-но | D21: Свинина по тайски с рисом | E21: 26 | F21: 26 | AY21: =(E21+G21+I21+K21+M21+O21+Q21+S21+U21+W21+Y21+AA21+AC21+AE21+AG21+AI21+AK21+AM21+AW21+AO21+AQ21+AS21+AU21)+1 -> 27 | AZ21: =F21+H21+J21+L21+N21+P21+R21+T21+V21+X21+Z21+AD21+AB21+AF21+AH21+AJ21+AL21+AR21+AX21+AN21+AP21+AT21+AV21 -> 26 | BA21: =188*(AZ21-AX21) -> 4888
A22: 21 | B22: 3517 | C22: Доп-но | D22: Тефтели рыбные с пюре | E22: 25 | F22: 28 | AY22: =(E22+G22+I22+K22+M22+O22+Q22+S22+U22+W22+Y22+AA22+AC22+AE22+AG22+AI22+AK22+AM22+AW22+AO22+AQ22+AS22+AU22)+1 -> 26 | AZ22: =F22+H22+J22+L22+N22+P22+R22+T22+V22+X22+Z22+AD22+AB22+AF22+AH22+AJ22+AL22+AR22+AX22+AN22+AP22+AT22+AV22 -> 28 | BA22: =188*(AZ22-AX22) -> 5264
A23: 22 | B23: 2531 | C23: Доп-но | D23: Хлеб | E23: 10 | F23: 11 | K23: 15 | L23: 15 | O23: 5 | P23: 5 | S23: 5 | T23: 5 | W23: 5 | X23: 5 | Y23: 3 | Z23: 3 | AE23: 3 | AF23: 3 | AK23: 3 | AL23: 3 | AQ23: 0 | AU23: 0 | AY23: =(E23+G23+I23+K23+M23+O23+Q23+S23+U23+W23+Y23+AA23+AC23+AE23+AG23+AI23+AK23+AM23+AW23+AO23+AQ23+AS23+AU23)+1 -> 50 | AZ23: =F23+H23+J23+L23+N23+P23+R23+T23+V23+X23+Z23+AD23+AB23+AF23+AH23+AJ23+AL23+AR23+AX23+AN23+AP23+AT23+AV23 -> 50 | BA23: =198*AZ23 -> 9900
A24: 23 | B24: 5 | C24: ='Матрица 4 недели'!S3 -> Сэндвич | AY24: =(E24+G24+I24+K24+M24+O24+Q24+S24+U24+W24+Y24+AA24+AC24+AE24+AG24+AI24+AK24+AM24+AW24+AO24+AQ24+AS24+AU24)+1 -> 1 | AZ24: =F24+H24+J24+L24+N24+P24+R24+T24+V24+X24+Z24+AD24+AB24+AF24+AH24+AJ24+AL24+AR24+AX24+AN24+AP24+AT24+AV24 -> 0 | BA24: =160*AZ24 -> 0 | BC24: 0.16 | BD24: =AY24*BC24 -> 0.16
A25: 24 | C25: ='Матрица 4 недели'!S145 -> Сэндвич | AY25: =(E25+G25+I25+K25+M25+O25+Q25+S25+U25+W25+Y25+AA25+AC25+AE25+AG25+AI25+AK25+AM25+AW25+AO25+AQ25+AS25+AU25)+1 -> 1 | AZ25: =F25+H25+J25+L25+N25+P25+R25+T25+V25+X25+Z25+AD25+AB25+AF25+AH25+AJ25+AL25+AR25+AX25+AN25+AP25+AT25+AV25 -> 0 | BA25: =155*AZ25 -> 0
A26: 25 | B26: 3518 | C26: Выпечка | AY26: =(E26+G26+I26+K26+M26+O26+Q26+S26+U26+W26+Y26+AA26+AC26+AE26+AG26+AI26+AK26+AM26+AW26+AO26+AQ26+AS26+AU26)+1 -> 1 | AZ26: =F26+H26+J26+L26+N26+P26+R26+T26+V26+X26+Z26+AD26+AB26+AF26+AH26+AJ26+AL26+AR26+AX26+AN26+AP26+AT26+AV26 -> 0
A27: 26 | C27: Выпечка | AY27: =(E27+G27+I27+K27+M27+O27+Q27+S27+U27+W27+Y27+AA27+AC27+AE27+AG27+AI27+AK27+AM27+AW27+AO27+AQ27+AS27+AU27)+1 -> 1 | AZ27: =F27+H27+J27+L27+N27+P27+R27+T27+V27+X27+Z27+AD27+AB27+AF27+AH27+AJ27+AL27+AR27+AX27+AN27+AP27+AT27+AV27 -> 0
A28: 27 | C28: ='Матрица 4 недели'!P145 -> Выпечка | AY28: =(E28+G28+I28+K28+M28+O28+Q28+S28+U28+W28+Y28+AA28+AC28+AE28+AG28+AI28+AK28+AM28+AW28+AO28+AQ28+AS28+AU28)+1 -> 1 | AZ28: =F28+H28+J28+L28+N28+P28+R28+T28+V28+X28+Z28+AD28+AB28+AF28+AH28+AJ28+AL28+AR28+AX28+AN28+AP28+AT28+AV28 -> 0
A29: 28 | B29: 822 | C29: Внеплан | AY29: =(E29+G29+I29+K29+M29+O29+Q29+S29+U29+W29+Y29+AA29+AC29+AE29+AG29+AI29+AK29+AM29+AW29+AO29+AQ29+AS29+AU29)+1 -> 1 | AZ29: =F29+H29+J29+L29+N29+P29+R29+T29+V29+X29+Z29+AD29+AB29+AF29+AH29+AJ29+AL29+AR29+AX29+AN29+AP29+AT29+AV29 -> 0 | BB29: =AX29*5 -> 0
A30: 29 | C30: Внеплан | AY30: =(E30+G30+I30+K30+M30+O30+Q30+S30+U30+W30+Y30+AA30+AC30+AE30+AG30+AI30+AK30+AM30+AW30+AO30+AQ30+AS30+AU30)+1 -> 1 | AZ30: =F30+H30+J30+L30+N30+P30+R30+T30+V30+X30+Z30+AD30+AB30+AF30+AH30+AJ30+AL30+AR30+AX30+AN30+AP30+AT30+AV30 -> 0
A31: 30 | C31: Внеплан | AY31: =(E31+G31+I31+K31+M31+O31+Q31+S31+U31+W31+Y31+AA31+AC31+AE31+AG31+AI31+AK31+AM31+AW31+AO31+AQ31+AS31+AU31)+1 -> 1 | AZ31: =F31+H31+J31+L31+N31+P31+R31+T31+V31+X31+Z31+AD31+AB31+AF31+AH31+AJ31+AL31+AR31+AX31+AN31+AP31+AT31+AV31 -> 0
A32: 31 | C32: Внеплан | AY32: =(E32+G32+I32+K32+M32+O32+Q32+S32+U32+W32+Y32+AA32+AC32+AE32+AG32+AI32+AK32+AM32+AW32+AO32+AQ32+AS32+AU32)+1 -> 1 | AZ32: =F32+H32+J32+L32+N32+P32+R32+T32+V32+X32+Z32+AD32+AB32+AF32+AH32+AJ32+AL32+AR32+AX32+AN32+AP32+AT32+AV32 -> 0
AY33: =SUM(AY6:AY32) -> 1307 | AZ33: =SUM(AZ6:AZ32) -> 1315 | BA33: =SUM(BA6:BA32) -> 200694 | BB33: =SUM(BB6:BB32) -> 1200 | BC33: вес | BD33: =SUM(BD6:BD24) -> 158.06
C34: ______________________________________________________________________________________ | BA34: =BA33+BB33 -> 201894
A36: Дата: | C36: =C2 -> 45659 | D36: Загрузка в аппараты | I36: Выгружаем дату производства:
A37: № | B37: =B3 -> Код | C37: Вид | D37: Название блюда | E37: Т1 | G37: Т2 | I37: Т3 | K37: Т4 | M37: Т5 | O37: Т6 | Q37: Т7 | S37: Т8 | U37: Т9 | W37: Т10 | Y37: Т11 | AA37: Т12 | AC37: Т13 | AE37: Т14 | AG37: Т15 | AI37: Т16 | AK37: Т17 | AM37: Т18 | AO37: Т19 | AQ37: Т20 | AS37: Т21 | AU37: Т22 | AW37: СПК | AY37: ИТОГ
A38: =A6 -> 1 | B38: =B6 -> 2423 | C38: =C6 -> Завтрак | D38: =D6 | E38: =F6 -> 20 | G38: =H6 | I38: =J6 | K38: =L6 -> 10 | M38: =N6 | O38: =P6 -> 9 | Q38: =R6 | S38: =T6 -> 5 | U38: =V6 | W38: =X6 -> 10 | Y38: =Z6 -> 5 | AA38: =AB6 | AC38: =AD6 | AE38: =AF6 -> 5 | AG38: =AH6 | AI38: =AJ6 | AK38: =AL6 -> 5 | AM38: =AN6 | AO38: =AP6 | AQ38: =AR6 -> 10 | AS38: =AT6 | AU38: =AV6 -> 8 | AW38: =AX6 | AY38: =SUM(E38:AX38) -> 87
A39: =A7 -> 2 | B39: =B7 -> 3624 | C39: =C7 -> Завтрак | D39: =D7 | E39: =F7 -> 20 | G39: =H7 | I39: =J7 | K39: =L7 -> 10 | M39: =N7 | O39: =P7 -> 9 | Q39: =R7 | S39: =T7 -> 5 | U39: =V7 | W39: =X7 -> 10 | Y39: =Z7 -> 5 | AA39: =AB7 | AC39: =AD7 | AE39: =AF7 -> 5 | AG39: =AH7 | AI39: =AJ7 | AK39: =AL7 -> 5 | AM39: =AN7 | AO39: =AP7 | AQ39: =AR7 -> 10 | AS39: =AT7 | AU39: =AV7 -> 8 | AW39: =AX7 | AY39: =SUM(E39:AX39) -> 87
A40: =A8 -> 3 | B40: =B8 -> 3170 | C40: =C8 -> салат | D40: =D8 | E40: =F8 -> 30 | G40: =H8 | I40: =J8 | K40: =L8 -> 5 | M40: =N8 | O40: =P8 | Q40: =R8 | S40: =T8 | U40: =V8 | W40: =X8 -> 5 | Y40: =Z8 | AA40: =AB8 | AC40: =AD8 | AE40: =AF8 | AG40: =AH8 | AI40: =AJ8 | AK40: =AL8 | AM40: =AN8 | AO40: =AP8 | AQ40: =AR8 -> 20 | AS40: =AT8 | AU40: =AV8 | AW40: =AX8 | AY40: =SUM(E40:AX40) -> 60
A41: =A9 -> 4 | B41: =B9 -> 47 | C41: =C9 -> Салат | D41: =D9 | E41: =F9 -> 30 | G41: =H9 | I41: =J9 | K41: =L9 -> 10 | M41: =N9 | O41: =P9 -> 15 | Q41: =R9 | S41: =T9 -> 5 | U41: =V9 | W41: =X9 -> 13 | Y41: =Z9 -> 5 | AA41: =AB9 | AC41: =AD9 | AE41: =AF9 -> 10 | AG41: =AH9 | AI41: =AJ9 | AK41: =AL9 -> 7 | AM41: =AN9 | AO41: =AP9 | AQ41: =AR9 -> 20 | AS41: =AT9 | AU41: =AV9 -> 20 | AW41: =AX9 | AY41: =SUM(E41:AX41) -> 135
...

Sheet Рабочие дни в праздники
A2: № точки | B2: Адреса | C2: 29.30.12 | D2: 46021 | E2: 46022 | F2: 46023 | G2: 46024 | H2: 46025 | I2: 46026 | J2: 46027 | K2: 46028 | L2: 46029 | M2: 46030 | N2: 46031 | O2: 46032 | P2: 46033 | Q2: 46034 | R2: Информация
A3: 1 | B3: "Лемана Про" ул. Тобольский тракт д.103 | E3: 100-105 | H3: В обычном режиме | J3: В обычном режиме | L3: В обычном режиме | N3: В обычном режиме | P3: В обычном режиме | R3: С 31.12 - 04.01 НЕ БУДЕТ РАБОТАТЬ СТОЛОВАЯ 31 магазин работает с 9 до 18, 1 числа выходной и с 2 числа как обычно
A4: 2 | B4: Пермякова 1Г, Очаково
A5: 3 | B5: Велижанский тракт 6 км, ст9 "ЗапСибГазпром Газификация" | R5: с 31.12 по 11.01 отдыхают, 12.01 на работу
A6: 4 | B6: Старый Тобольский тракт 2 километр, 8 ст25 "Технологии офс" | E6: ~40 | F6: ~40 | G6: ~40 | H6: ~40 | I6: ~40 | J6: ~40 | K6: ~40 | L6: ~40 | M6: ~40 | N6: ~40 | O6: ~40 | P6: ~40 | R6: Все праздники работает только круглосуточный персонал, около 30 человек
A7: 5 | B7: "Бентек" Старый Тобольский тракт 2 километр, 8а | J7: ~20 | K7: ~20 | L7: ~20 | M7: ~20 | N7: ~20 | O7: ~20 | P7: ~20 | R7: 31-4 выходные, с 5го по 11е работают примерно по 20 чел
A8: 6 | B8: "ОФС" Тобольский тракт 23 км | R8: 31.12 - сокращеный день до 16:00, 1.01 - выходной у всех, с 02.01 - цех работает, кроме начальства и технологического отдела. с 12.01 в штатном режиме
A9: 7 | B9: ул. Сергея Ильюшина,1 Металл Профиль | C9: ~30 | D9: ~30 | R9: 29-30 крайние рабочие дни будет 30 чел., половина сотрудников в эти дни не выйдут на работу, тк берут за свой счет. На работу выходим 12.01
A10: 8 | B10: Тубдиспансер, Курортная 2а | R10: Загрузка по выходному дню
A11: 9 | B11: ул. Камчатская, 194 "АИРТО" | R11: как и во все праздничные дни мы в праздники будем отдыхать. И Арендаторы (большинство) тоже.
A12: 10 | B12: Станция скорой помощи, Суходольская д. 25 | F12: В обычном режиме | H12: В обычном режиме | J12: В обычном режиме | L12: В обычном режиме | N12: В обычном режиме | P12: В обычном режиме | R12: Работают в обычном режиме
A13: 11 | B13: Катрен, Гилёвская Роща д.10 | R13: 30.12, 31.12, 01.01 и 7.01 - выходные дни, остальные рабочие (загруженость на 7-10% сеньше чем обчно)
A14: 12 | B14: ул. Республики, 250 "Сантехкомплект" (малое АБК) | R14: Работают по производственному календарю
A15: 13 | B15: ул. Республики, 250 "Сантехкомплект"
A16: 14 | B16: ул. Республики, 142 "Технопарк" | E16: ~15-20 | F16: ~15-20 | G16: ~15-20 | H16: ~15-20 | I16: ~15-20 | J16: ~15-20 | K16: ~15-20 | L16: ~15-20 | M16: ~15-20 | N16: ~15-20 | O16: ~15-20 | P16: ~15-20 | R16: Примерно будут работать 15/20 человек в смену, загрузка выходного дня
A17: 15 | B17: ул. Депутатская 91, к. 3 "АТМ Альянс" | R17: с 31.12 по 11.01 отдыхают, 12.01 на работу
A18: 16 | B18: ул. Первомайская 19 "Запсибгазпром" | R18: с 31.12 по 11.01 отдыхают, 12.01 на работу
A19: 17 | B19: Республики 211 а | E19: ~30 | F19: ~10-15 | G19: ~10-15 | H19: ~10-15 | I19: ~10-15 | J19: ~30-50 | K19: ~30-50 | L19: ~30-50 | M19: ~30-50 | N19: ~30-50 | O19: ~30-50 | P19: ~30-50
A20: 18 | B20: Тюмень прибор, Индустриальный парк Боровский Промзона Южная, ст5 | R20: с 31.12 по 11.01 отдыхают, 12.01 на работу
A21: 19 | B21: ул. Республики, 142 "Технопарк"2 | R21: с 31.12 по 11.01 отдыхают, 12.01 на работу
A22: 20 | B22: ул. Даудельная 1к3 | F22: В обычном режиме | H22: В обычном режиме | J22: В обычном режиме | L22: В обычном режиме | N22: В обычном режиме | P22: В обычном режиме | R22: Работают в обычном режиме
A23: 21 | B23: "Шлюмберже" ул. Дружбы, 124 | I23: 20 | J23: 20 | K23: 20 | L23: 20 | M23: 20 | N23: 20 | O23: 20 | P23: 20 | R23: с 31.12 по 03.01 отдыхают, с 04.01 будут работать по 20 человек, остальные выходят 12.01
A24: 22 | B24: "Лемана Про" ул. Менделеева 1 | H24: В обычном режиме | J24: В обычном режиме | L24: В обычном режиме | N24: В обычном режиме | P24: В обычном режиме
A25: СПК | B25: СПК завод, Республики 250 (обеденная загрузка) | R25: Работают по производственному календарю
A26: БАХАРЕВА | C26: 15 | D26: 15 | E26: 15 | F26: 45780 | G26: 45780 | H26: 45780 | I26: 45780 | J26: 45780 | R26: С 1-5 ПРИМЕРНО 3-5 ЧЕЛ. ЕСЛИ НЕ РАБОТАЕМ - ЧЕМ НАКОРМИТЬ РЗБЕРУТСЯ
E28: Выходные
E29: Короткий день до 18:00
E30: Короткий день до 16:00

Sheet Детали
A1: Код блюда | B1: Название блюда | C1: Код белка | D1: Белок | E1: Код гарнира | F1: Гарнир | G1: Статус | H1: Комментарий
A2: 1050 | B2: Азу ''По-татарски'' | C2: 3906 | D2: Азу из свинины с грибами б/100гр | G2: не найден гарнир
A3: 3025 | B3: Азу ''По-татарски'' (Столовая) | C3: 3906 | D3: Азу из свинины с грибами б/100гр | G3: не найден гарнир
A4: 3362 | B4: Азу из говядины с гречкой | E4: 2263 | F4: Гречка г/200гр | G4: не найден белок
A5: 3351 | B5: Азу из говядины с макаронами | E5: 2278 | F5: Макароны г/200гр | G5: не найден белок
A6: 3462 | B6: Азу из говядины с пюре | E6: 2247 | F6: Картофельное пюре г/200гр | G6: не найден белок
A7: 3361 | B7: Азу из говядины с рисом | E7: 487 | F7: Рис г/150гр | G7: не найден белок
A8: 3352 | B8: Азу из курицы с картофелем | E8: 2247 | F8: Картофельное пюре г/200гр | G8: не найден белок
A9: 3405 | B9: Азу из курицы с рисом | E9: 487 | F9: Рис г/150гр | G9: не найден белок
A10: 3303 | B10: Азу из курицы со спагетти | E10: 2264 | F10: Спагетти г/150гр | G10: не найден белок
A11: 3541 | B11: Азу из курочки с гречкой | E11: 2263 | F11: Гречка г/200гр | G11: не найден белок
A12: 2163 | B12: Азу из курочки с макаронами | E12: 2278 | F12: Макароны г/200гр | G12: не найден белок
A13: 3307 | B13: Азу из курочки с соленым огурчиком (столовая) | G13: не найдено
A14: 219 | B14: Азу из свинины с грибами с рисом | C14: 3906 | D14: Азу из свинины с грибами б/100гр | E14: 487 | F14: Рис г/150гр | G14: авто
A15: 737 | B15: Айран 150 мл | G15: не найдено
A16: 2904 | B16: Ассорти сэндвич (пепперони/ветчина) | G16: не найдено
A17: 384 | B17: Бедро в сметанном соусе с картофелем | C17: 2249 | D17: Бедро запеченное б/шт | E17: 2247 | F17: Картофельное пюре г/200гр | G17: авто
A18: 804 | B18: Бедро в соусе сациви с гречкой | C18: 2249 | D18: Бедро запеченное б/шт | E18: 2263 | F18: Гречка г/200гр | G18: авто
A19: 642 | B19: Бедро в соусе сациви с рисом | C19: 2249 | D19: Бедро запеченное б/шт | E19: 487 | F19: Рис г/150гр | G19: авто
A20: 370 | B20: Бедро жареное | G20: не найдено
A21: 886 | B21: Бедро запеченное с гречкой | C21: 2249 | D21: Бедро запеченное б/шт | E21: 2263 | F21: Гречка г/200гр | G21: авто
A22: 372 | B22: Бедро запеченное с картофелем | C22: 2249 | D22: Бедро запеченное б/шт | E22: 2247 | F22: Картофельное пюре г/200гр | G22: авто
A23: 984 | B23: Бедро запеченное с картофельным пюре | C23: 2249 | D23: Бедро запеченное б/шт | E23: 2247 | F23: Картофельное пюре г/200гр | G23: авто
A24: 859 | B24: Бедро запеченное с макаронами | C24: 2249 | D24: Бедро запеченное б/шт | E24: 2278 | F24: Макароны г/200гр | G24: авто
A25: 885 | B25: Бедро запеченное с рисом | C25: 2249 | D25: Бедро запеченное б/шт | E25: 487 | F25: Рис г/150гр | G25: авто
A26: 1080 | B26: Бедро запеченное с тушеной капустой | C26: 2249 | D26: Бедро запеченное б/шт | E26: 2248 | F26: Капуста тушеная г/150гр | G26: авто
A27: 2019 | B27: Бедро запеченное со ''сложным гарниром'' | C27: 2249 | D27: Бедро запеченное б/шт | G27: не найден гарнир
A28: 1122 | B28: Бедро запеченное со спагетти | C28: 2249 | D28: Бедро запеченное б/шт | E28: 2264 | F28: Спагетти г/150гр | G28: авто
A29: 2249 | B29: Бедро запеченое (горячее) Столовая | C29: 2249 | D29: Бедро запеченное б/шт | G29: не найден гарнир
A30: 143 | B30: Бедро под шапочкой с овощным сотэ | G30: не найдено
A31: 146 | B31: Бедро под шапочкой со спагетти | E31: 2264 | F31: Спагетти г/150гр | G31: не найден белок
A32: 1040 | B32: Бедрышки жареные с пюре | E32: 2247 | F32: Картофельное пюре г/200гр | G32: не найден белок
A33: 1345 | B33: Беляш | G33: не найдено
A34: 681 | B34: Бефстроганов из курочки со спагетти | E34: 2264 | F34: Спагетти г/150гр | G34: не найден белок
A35: 606 | B35: Бефстроганов с гречкой | E35: 2263 | F35: Гречка г/200гр | G35: не найден белок
A36: 2092 | B36: Бефстроганов со сливочным пюре | E36: 2247 | F36: Картофельное пюре г/200гр | G36: не найден белок
A37: 762 | B37: Бигус со свининой | G37: не найдено
A38: 439 | B38: Биточек ''по-селянски'' с лапшой | C38: 1269 | D38: Биточек куриный б/шт | G38: не найден гарнир
A39: 436 | B39: Биточек ''по-селянски'' со спагетти | C39: 1269 | D39: Биточек куриный б/шт | E39: 2264 | F39: Спагетти г/150гр | G39: авто
A40: 2895 | B40: Биточек ''Солнышко'' (Столовая) | G40: не найдено
...

Sheet Динамика 2 мес
A1: =IFERROR(__xludf.DUMMYFUNCTION("IMPORTRANGE(""https://docs.google.com/spreadsheets/d/1Yb5TdnkO_G1YtSRao6XpO7iTs35tl-2Ggkk8F2yHY3A/edit"",""_service_dashboard_vm!A1:s40"")"),"Период прошлый") -> Период прошлый | B1: =IFERROR(__xludf.DUMMYFUNCTION("""COMPUTED_VALUE"""),"01.07.2026 - 19.07.2026") -> 01.07.2026 - 19.07.2026 | O1: =IFERROR(__xludf.DUMMYFUNCTION("""COMPUTED_VALUE"""),"метрика") -> метрика | P1: =IFERROR(__xludf.DUMMYFUNCTION("""COMPUTED_VALUE"""),"прошлый") -> прошлый | Q1: =IFERROR(__xludf.DUMMYFUNCTION("""COMPUTED_VALUE"""),"текущий") -> текущий | R1: =IFERROR(__xludf.DUMMYFUNCTION("""COMPUTED_VALUE"""),"разница") -> разница | S1: =IFERROR(__xludf.DUMMYFUNCTION("""COMPUTED_VALUE"""),"разница %") -> разница %
A2: =IFERROR(__xludf.DUMMYFUNCTION("""COMPUTED_VALUE"""),"Период текущий") -> Период текущий | B2: =IFERROR(__xludf.DUMMYFUNCTION("""COMPUTED_VALUE"""),"01.08.2026 - 19.08.2026") -> 01.08.2026 - 19.08.2026 | O2: =IFERROR(__xludf.DUMMYFUNCTION("""COMPUTED_VALUE"""),"СР. Выручка") -> СР. Выручка | P2: =IFERROR(__xludf.DUMMYFUNCTION("""COMPUTED_VALUE"""),239437.90499223) -> 239437.9 | Q2: =IFERROR(__xludf.DUMMYFUNCTION("""COMPUTED_VALUE"""),248696.71209595964) -> 248696.71 | R2: =IFERROR(__xludf.DUMMYFUNCTION("""COMPUTED_VALUE"""),9258.807103729632) -> 9258.8071 | S2: =IFERROR(__xludf.DUMMYFUNCTION("""COMPUTED_VALUE"""),0.03866892797959492) -> 0.038668928
A3: =IFERROR(__xludf.DUMMYFUNCTION("""COMPUTED_VALUE"""),"Обновлено") -> Обновлено | B3: =IFERROR(__xludf.DUMMYFUNCTION("""COMPUTED_VALUE"""),46253.38116664352) -> 46253.381 | O3: =IFERROR(__xludf.DUMMYFUNCTION("""COMPUTED_VALUE"""),"СР. Кол-во чеков") -> СР. Кол-во чеков | P3: =IFERROR(__xludf.DUMMYFUNCTION("""COMPUTED_VALUE"""),1275.2971250971252) -> 1275.2971 | Q3: =IFERROR(__xludf.DUMMYFUNCTION("""COMPUTED_VALUE"""),1311.7416666666668) -> 1311.7417 | R3: =IFERROR(__xludf.DUMMYFUNCTION("""COMPUTED_VALUE"""),36.44454156954157) -> 36.444542 | S3: =IFERROR(__xludf.DUMMYFUNCTION("""COMPUTED_VALUE"""),0.028577294539706574) -> 0.028577295 | T3: =R3*Q4 -> 6760.9485 | U3: результат по количеству чеков
B4: =IFERROR(__xludf.DUMMYFUNCTION("""COMPUTED_VALUE"""),"СР. ВЫРУЧКА") -> СР. ВЫРУЧКА | D4: =IFERROR(__xludf.DUMMYFUNCTION("""COMPUTED_VALUE"""),-0.48823775531127006) -> -0.48823776 | E4: =IFERROR(__xludf.DUMMYFUNCTION("""COMPUTED_VALUE"""),"СР. КОЛ-ВО ЧЕКОВ") -> СР. КОЛ-ВО ЧЕКОВ | G4: =IFERROR(__xludf.DUMMYFUNCTION("""COMPUTED_VALUE"""),-0.9592566208111047) -> -0.95925662 | H4: =IFERROR(__xludf.DUMMYFUNCTION("""COMPUTED_VALUE"""),"СР. СРЕДНИЙ ЧЕК") -> СР. СРЕДНИЙ ЧЕК | J4: =IFERROR(__xludf.DUMMYFUNCTION("""COMPUTED_VALUE"""),0.44601209679013254) -> 0.4460121 | K4: =IFERROR(__xludf.DUMMYFUNCTION("""COMPUTED_VALUE"""),"СПИСАНИЯ") -> СПИСАНИЯ | M4: =IFERROR(__xludf.DUMMYFUNCTION("""COMPUTED_VALUE"""),4.721302653747017) -> 4.7213027 | O4: =IFERROR(__xludf.DUMMYFUNCTION("""COMPUTED_VALUE"""),"СР. Средний чек") -> СР. Средний чек | P4: =IFERROR(__xludf.DUMMYFUNCTION("""COMPUTED_VALUE"""),165.01639240410128) -> 165.01639 | Q4: =IFERROR(__xludf.DUMMYFUNCTION("""COMPUTED_VALUE"""),185.51333668847326) -> 185.51334 | R4: =IFERROR(__xludf.DUMMYFUNCTION("""COMPUTED_VALUE"""),20.496944284371978) -> 20.496944 | S4: =IFERROR(__xludf.DUMMYFUNCTION("""COMPUTED_VALUE"""),0.12421156459521866) -> 0.12421156 | T4: =Q3*R4 -> 26886.696 | U4: результат по среднему чеку
A5: =IFERROR(__xludf.DUMMYFUNCTION("""COMPUTED_VALUE"""),"Точка") -> Точка | B5: =IFERROR(__xludf.DUMMYFUNCTION("""COMPUTED_VALUE"""),"Прошлый") -> Прошлый | C5: =IFERROR(__xludf.DUMMYFUNCTION("""COMPUTED_VALUE"""),"Текущий") -> Текущий | D5: =IFERROR(__xludf.DUMMYFUNCTION("""COMPUTED_VALUE"""),"%") -> % | E5: =IFERROR(__xludf.DUMMYFUNCTION("""COMPUTED_VALUE"""),"Прошлый") -> Прошлый | F5: =IFERROR(__xludf.DUMMYFUNCTION("""COMPUTED_VALUE"""),"Текущий") -> Текущий | G5: =IFERROR(__xludf.DUMMYFUNCTION("""COMPUTED_VALUE"""),"%") -> % | H5: =IFERROR(__xludf.DUMMYFUNCTION("""COMPUTED_VALUE"""),"Прошлый") -> Прошлый | I5: =IFERROR(__xludf.DUMMYFUNCTION("""COMPUTED_VALUE"""),"Текущий") -> Текущий | J5: =IFERROR(__xludf.DUMMYFUNCTION("""COMPUTED_VALUE"""),"%") -> % | K5: =IFERROR(__xludf.DUMMYFUNCTION("""COMPUTED_VALUE"""),"Прошлый") -> Прошлый | L5: =IFERROR(__xludf.DUMMYFUNCTION("""COMPUTED_VALUE"""),"Текущий") -> Текущий | M5: =IFERROR(__xludf.DUMMYFUNCTION("""COMPUTED_VALUE"""),"%") -> % | N5: =IFERROR(__xludf.DUMMYFUNCTION("""COMPUTED_VALUE"""),"Активна") -> Активна | O5: =IFERROR(__xludf.DUMMYFUNCTION("""COMPUTED_VALUE"""),"Списания") -> Списания | P5: =IFERROR(__xludf.DUMMYFUNCTION("""COMPUTED_VALUE"""),208596.07) -> 208596.07 | Q5: =IFERROR(__xludf.DUMMYFUNCTION("""COMPUTED_VALUE"""),238274.44) -> 238274.44 | R5: =IFERROR(__xludf.DUMMYFUNCTION("""COMPUTED_VALUE"""),29678.369999999995) -> 29678.37 | S5: =IFERROR(__xludf.DUMMYFUNCTION("""COMPUTED_VALUE"""),0.14227674567406756) -> 0.14227675
A6: =IFERROR(__xludf.DUMMYFUNCTION("""COMPUTED_VALUE"""),"0") -> 0 | B6: =IFERROR(__xludf.DUMMYFUNCTION("""COMPUTED_VALUE"""),147.0) -> 147 | C6: =IFERROR(__xludf.DUMMYFUNCTION("""COMPUTED_VALUE"""),192.0) -> 192 | D6: =IFERROR(__xludf.DUMMYFUNCTION("""COMPUTED_VALUE"""),0.30612244897959184) -> 0.30612245 | E6: =IFERROR(__xludf.DUMMYFUNCTION("""COMPUTED_VALUE"""),1.0) -> 1 | F6: =IFERROR(__xludf.DUMMYFUNCTION("""COMPUTED_VALUE"""),1.0) -> 1 | G6: =IFERROR(__xludf.DUMMYFUNCTION("""COMPUTED_VALUE"""),0.0) -> 0 | H6: =IFERROR(__xludf.DUMMYFUNCTION("""COMPUTED_VALUE"""),147.0) -> 147 | I6: =IFERROR(__xludf.DUMMYFUNCTION("""COMPUTED_VALUE"""),192.0) -> 192 | J6: =IFERROR(__xludf.DUMMYFUNCTION("""COMPUTED_VALUE"""),0.30612244897959184) -> 0.30612245 | K6: =IFERROR(__xludf.DUMMYFUNCTION("""COMPUTED_VALUE"""),0.0) -> 0 | L6: =IFERROR(__xludf.DUMMYFUNCTION("""COMPUTED_VALUE"""),0.0) -> 0 | N6: =IFERROR(__xludf.DUMMYFUNCTION("""COMPUTED_VALUE"""),"нет") -> нет
A7: =IFERROR(__xludf.DUMMYFUNCTION("""COMPUTED_VALUE"""),"1") -> 1 | B7: =IFERROR(__xludf.DUMMYFUNCTION("""COMPUTED_VALUE"""),16876.603846153845) -> 16876.604 | C7: =IFERROR(__xludf.DUMMYFUNCTION("""COMPUTED_VALUE"""),16597.12916666667) -> 16597.129 | D7: =IFERROR(__xludf.DUMMYFUNCTION("""COMPUTED_VALUE"""),-0.016559888591025213) -> -0.016559889 | E7: =IFERROR(__xludf.DUMMYFUNCTION("""COMPUTED_VALUE"""),101.84615384615384) -> 101.84615 | F7: =IFERROR(__xludf.DUMMYFUNCTION("""COMPUTED_VALUE"""),99.0) -> 99 | G7: =IFERROR(__xludf.DUMMYFUNCTION("""COMPUTED_VALUE"""),-0.02794561933534737) -> -0.027945619 | H7: =IFERROR(__xludf.DUMMYFUNCTION("""COMPUTED_VALUE"""),166.2771121498758) -> 166.27711 | I7: =IFERROR(__xludf.DUMMYFUNCTION("""COMPUTED_VALUE"""),167.47542196011383) -> 167.47542 | J7: =IFERROR(__xludf.DUMMYFUNCTION("""COMPUTED_VALUE"""),0.007206703284321738) -> 0.0072067033 | K7: =IFERROR(__xludf.DUMMYFUNCTION("""COMPUTED_VALUE"""),39720.110000000015) -> 39720.11 | L7: =IFERROR(__xludf.DUMMYFUNCTION("""COMPUTED_VALUE"""),14923.240000000003) -> 14923.24 | M7: =IFERROR(__xludf.DUMMYFUNCTION("""COMPUTED_VALUE"""),-0.62429006364786) -> -0.62429006 | N7: =IFERROR(__xludf.DUMMYFUNCTION("""COMPUTED_VALUE"""),"да") -> да
A8: =IFERROR(__xludf.DUMMYFUNCTION("""COMPUTED_VALUE"""),"2") -> 2 | B8: =IFERROR(__xludf.DUMMYFUNCTION("""COMPUTED_VALUE"""),5142.2692307692305) -> 5142.2692 | C8: =IFERROR(__xludf.DUMMYFUNCTION("""COMPUTED_VALUE"""),4533.595833333334) -> 4533.5958 | D8: =IFERROR(__xludf.DUMMYFUNCTION("""COMPUTED_VALUE"""),-0.1183666918476078) -> -0.11836669 | E8: =IFERROR(__xludf.DUMMYFUNCTION("""COMPUTED_VALUE"""),25.307692307692307) -> 25.307692 | F8: =IFERROR(__xludf.DUMMYFUNCTION("""COMPUTED_VALUE"""),23.0) -> 23 | G8: =IFERROR(__xludf.DUMMYFUNCTION("""COMPUTED_VALUE"""),-0.09118541033434646) -> -0.09118541 | H8: =IFERROR(__xludf.DUMMYFUNCTION("""COMPUTED_VALUE"""),218.05265432030012) -> 218.05265 | I8: =IFERROR(__xludf.DUMMYFUNCTION("""COMPUTED_VALUE"""),198.84553974196209) -> 198.84554 | J8: =IFERROR(__xludf.DUMMYFUNCTION("""COMPUTED_VALUE"""),-0.08808475474976094) -> -0.088084755 | K8: =IFERROR(__xludf.DUMMYFUNCTION("""COMPUTED_VALUE"""),1385.8200000000002) -> 1385.82 | L8: =IFERROR(__xludf.DUMMYFUNCTION("""COMPUTED_VALUE"""),4491.51) -> 4491.51 | M8: =IFERROR(__xludf.DUMMYFUNCTION("""COMPUTED_VALUE"""),2.2410486210330345) -> 2.2410486 | N8: =IFERROR(__xludf.DUMMYFUNCTION("""COMPUTED_VALUE"""),"да") -> да
